Workbook

Sheet Cost Margin
A1: Cost margin sheet
A2: Yellow = inputs (blue text). Grey = calculated. * = required. Pick the engagement type first — it decides how revenue is counted.
S3: Project summary
A4: Engagement type * (pick first) | B4: Assessment | C4: Fixed cost / Assessment → fill Total project price. MSP → fill Monthly fee. Time & materials → bill rates on each row are used. Fields not needed for the chosen type turn grey. | S4: Engagement type | T4: =IF(B4="","",B4) -> Assessment
A5: Project name | B5: AI Assessment | S5: Duration (months) | T5: =B10 -> 0.96129032
A6: Client | B6: Peppermill | S6: Project revenue | T6: =IF(B4="","",IF(B4="MSP",IF(OR(B12="",B10=""),"",B12*B10),IF(B4="Time & materials",M37,IF(B11="","",B11)))) -> 50000
A7: Currency | B7: USD | S7: Pass-through expenses billed to client | T7: =H53 -> 0
A8: Project start * | B8: 46272 | S8: Total revenue | T8: =IF(T6="","",T6+T7) -> 50000
A9: Project end * | B9: 46300 | S9: Labour cost | T9: =N37 -> 27416.122
A10: Duration (months, partial months by days) | B10: =IF(OR(B8="",B9=""),"",SUM(Monthly!$C$4:$Z$4)) -> 0.96129032 | C10: =IF(OR(B8="",B9=""),"",IF(B9<B8,"End is before start",DATEDIF(B8,B9+1,"M")&" month(s) "&DATEDIF(B8,B9+1,"MD")&" day(s) — "&(B9-B8+1)&" calendar days inclusive")) -> 0 month(s) 29 day(s) — 29 calendar days inclusive | S10: Burden cost | T10: =O37 -> 3143.0838
A11: Total project price * (Fixed cost / Assessment) | B11: 50000 | C11: =IF(OR(B4="Fixed cost",B4="Assessment"),IF(B11="","← required for this engagement type",""),IF(B11="","","Not used for this engagement type")) | S11: Additional costs | T11: =G53 -> 3000
A12: Monthly fee * (MSP) | C12: =IF(B4="MSP",IF(B12="","← required for MSP",""),IF(B12="","","Not used for this engagement type")) | S12: Total cost | T12: =T9+T10+T11 -> 33559.205
A13: Additional costs on this project? * (Y/N) | B13: Y | C13: =IF(B13="","← required: Y if there are travel, licences, subcontractor or other costs; N if none","") | S13: Gross margin $ | T13: =IF(T8="","",T8-T12) -> 16440.795
S14: Gross margin % | T14: =IF(OR(T8="",T8=0),"",T13/T8) -> 0.32881589
A15: Staffing — one row per person. To remove a person, select that row's yellow cells and press Delete; a row with no Role is ignored. (Rows can't be deleted — the Monthly tab maps to them.) | S15: Target GM % (blended floor) | T15: =IF(N37=0,"",SUMPRODUCT(N17:N36,Q17:Q36)/N37) -> 0.35
A16: Role * | B16: Seniority * | C16: Location * | D16: Utilization % | E16: Hours (auto type in Hours override to change) | F16: Bill rate (what we CHARGE the client per hour — T&M only) | G16: Our cost / hour * (what the person COSTS us per hour, before burden, pre-filled from the Settings rate card; overwrite if known) | H16: Start (pre-filled from project start, change if the person joins later) | I16: End (pre-filled from project end, change if they leave earlier) | J16: Working days | K16: Hours override (optional) | L16: Burden % | M16: Labour at bill rate (T&M revenue) | N16: Labour cost (hours × cost/hr) | O16: Burden cost | P16: Loaded cost (labour + burden) | Q16: GM floor % | S16: Status | T16: =IF(T18<>"","INCOMPLETE — see below",IF(OR(T14="",T15=""),"",IF(T14>=T15,"PASS","BELOW FLOOR"))) -> BELOW FLOOR
A17: Vikrin | B17: Senior | C17: US | D17: 1 | E17: =IF(K17<>"",K17,IF(J17="","",J17*Settings!$B$3*IF(D17="",1,D17))) -> 168 | G17: 143 | H17: =IF(OR(A17="",$B$8=""),"",$B$8) -> 46272 | I17: =IF(OR(A17="",$B$9=""),"",$B$9) -> 46300 | J17: =IF(OR(A17="",IF(H17="",$B$8,H17)="",IF(I17="",$B$9,I17)=""),"",IFERROR(NETWORKDAYS(IF(H17="",$B$8,H17),IF(I17="",$B$9,I17),INDEX(Settings!$J$7:$M$60,0,MATCH(C17,Settings!$J$6:$M$6,0))),NETWORKDAYS(IF(H17="",$B$8,H17),IF(I17="",$B$9,I17)))) -> 21 | L17: 0.08 | M17: =IF(OR(E17="",F17=""),0,E17*F17) -> 0 | N17: =IF(OR(E17="",G17=""),0,E17*G17) -> 24024 | O17: =N17*L17 -> 1921.92 | P17: =N17+O17 -> 25945.92 | Q17: =IF(C17="",0,IFERROR(INDEX(Settings!$C$6:$C$9,MATCH(C17,Settings!$A$6:$A$9,0)),0)) -> 0.35
A18: srikanth | B18: Senior | C18: US | D18: 0.24 | E18: =IF(K18<>"",K18,IF(J18="","",J18*Settings!$B$3*IF(D18="",1,D18))) -> 40.32 | G18: 84.13 | H18: =IF(OR(A18="",$B$8=""),"",$B$8) -> 46272 | I18: =IF(OR(A18="",$B$9=""),"",$B$9) -> 46300 | J18: =IF(OR(A18="",IF(H18="",$B$8,H18)="",IF(I18="",$B$9,I18)=""),"",IFERROR(NETWORKDAYS(IF(H18="",$B$8,H18),IF(I18="",$B$9,I18),INDEX(Settings!$J$7:$M$60,0,MATCH(C18,Settings!$J$6:$M$6,0))),NETWORKDAYS(IF(H18="",$B$8,H18),IF(I18="",$B$9,I18)))) -> 21 | L18: 0.36 | M18: =IF(OR(E18="",F18=""),0,E18*F18) -> 0 | N18: =IF(OR(E18="",G18=""),0,E18*G18) -> 3392.1216 | O18: =N18*L18 -> 1221.1638 | P18: =N18+O18 -> 4613.2854 | Q18: =IF(C18="",0,IFERROR(INDEX(Settings!$C$6:$C$9,MATCH(C18,Settings!$A$6:$A$9,0)),0)) -> 0.35 | S18: Missing inputs | T18: =TRIM(IF(B4="","Engagement type. ","")&IF(OR(B8="",B9=""),"Project dates. ","")&IF(AND(OR(B4="Fixed cost",B4="Assessment"),B11=""),"Total project price. ","")&IF(AND(B4="MSP",B12=""),"Monthly fee. ","")&IF(B13="","Additional costs Y/N. ","")&IF(COUNTIF(I41:I52,"Pick*")>0,"Billed to client Y/N (column F) on additional cost rows. ","")&IF(COUNTIFS(A17:A36,"<>",G17:G36,"")>0,"Our cost/hour (column G) on staffing rows — pick Seniority + Location or type it. ","")&IF(AND(B4="Time & materials",COUNTIFS(A17:A36,"<>",F17:F36,"")>0),"Bill rate on T&M rows. ",""))
E19: =IF(K19<>"",K19,IF(J19="","",J19*Settings!$B$3*IF(D19="",1,D19))) | G19: =IFERROR(INDEX(Settings!$Q$7:$T$10,MATCH(B19,Settings!$P$7:$P$10,0),MATCH(C19,Settings!$Q$6:$T$6,0)),"") | H19: =IF(OR(A19="",$B$8=""),"",$B$8) | I19: =IF(OR(A19="",$B$9=""),"",$B$9) | J19: =IF(OR(A19="",IF(H19="",$B$8,H19)="",IF(I19="",$B$9,I19)=""),"",IFERROR(NETWORKDAYS(IF(H19="",$B$8,H19),IF(I19="",$B$9,I19),INDEX(Settings!$J$7:$M$60,0,MATCH(C19,Settings!$J$6:$M$6,0))),NETWORKDAYS(IF(H19="",$B$8,H19),IF(I19="",$B$9,I19)))) | L19: =IF(C19="",0,IFERROR(INDEX(Settings!$B$6:$B$9,MATCH(C19,Settings!$A$6:$A$9,0)),0)) -> 0 | M19: =IF(OR(E19="",F19=""),0,E19*F19) -> 0 | N19: =IF(OR(E19="",G19=""),0,E19*G19) -> 0 | O19: =N19*L19 -> 0 | P19: =N19+O19 -> 0 | Q19: =IF(C19="",0,IFERROR(INDEX(Settings!$C$6:$C$9,MATCH(C19,Settings!$A$6:$A$9,0)),0)) -> 0
E20: =IF(K20<>"",K20,IF(J20="","",J20*Settings!$B$3*IF(D20="",1,D20))) | G20: =IFERROR(INDEX(Settings!$Q$7:$T$10,MATCH(B20,Settings!$P$7:$P$10,0),MATCH(C20,Settings!$Q$6:$T$6,0)),"") | H20: =IF(OR(A20="",$B$8=""),"",$B$8) | I20: =IF(OR(A20="",$B$9=""),"",$B$9) | J20: =IF(OR(A20="",IF(H20="",$B$8,H20)="",IF(I20="",$B$9,I20)=""),"",IFERROR(NETWORKDAYS(IF(H20="",$B$8,H20),IF(I20="",$B$9,I20),INDEX(Settings!$J$7:$M$60,0,MATCH(C20,Settings!$J$6:$M$6,0))),NETWORKDAYS(IF(H20="",$B$8,H20),IF(I20="",$B$9,I20)))) | L20: =IF(C20="",0,IFERROR(INDEX(Settings!$B$6:$B$9,MATCH(C20,Settings!$A$6:$A$9,0)),0)) -> 0 | M20: =IF(OR(E20="",F20=""),0,E20*F20) -> 0 | N20: =IF(OR(E20="",G20=""),0,E20*G20) -> 0 | O20: =N20*L20 -> 0 | P20: =N20+O20 -> 0 | Q20: =IF(C20="",0,IFERROR(INDEX(Settings!$C$6:$C$9,MATCH(C20,Settings!$A$6:$A$9,0)),0)) -> 0 | S20: Monthly view | T20: =IF(B10="","",IF(B10>2,"Required — see Monthly tab","Not needed (≤ 2 months)")) -> Not needed (≤ 2 months)
E21: =IF(K21<>"",K21,IF(J21="","",J21*Settings!$B$3*IF(D21="",1,D21))) | G21: =IFERROR(INDEX(Settings!$Q$7:$T$10,MATCH(B21,Settings!$P$7:$P$10,0),MATCH(C21,Settings!$Q$6:$T$6,0)),"") | H21: =IF(OR(A21="",$B$8=""),"",$B$8) | I21: =IF(OR(A21="",$B$9=""),"",$B$9) | J21: =IF(OR(A21="",IF(H21="",$B$8,H21)="",IF(I21="",$B$9,I21)=""),"",IFERROR(NETWORKDAYS(IF(H21="",$B$8,H21),IF(I21="",$B$9,I21),INDEX(Settings!$J$7:$M$60,0,MATCH(C21,Settings!$J$6:$M$6,0))),NETWORKDAYS(IF(H21="",$B$8,H21),IF(I21="",$B$9,I21)))) | L21: =IF(C21="",0,IFERROR(INDEX(Settings!$B$6:$B$9,MATCH(C21,Settings!$A$6:$A$9,0)),0)) -> 0 | M21: =IF(OR(E21="",F21=""),0,E21*F21) -> 0 | N21: =IF(OR(E21="",G21=""),0,E21*G21) -> 0 | O21: =N21*L21 -> 0 | P21: =N21+O21 -> 0 | Q21: =IF(C21="",0,IFERROR(INDEX(Settings!$C$6:$C$9,MATCH(C21,Settings!$A$6:$A$9,0)),0)) -> 0
E22: =IF(K22<>"",K22,IF(J22="","",J22*Settings!$B$3*IF(D22="",1,D22))) | G22: =IFERROR(INDEX(Settings!$Q$7:$T$10,MATCH(B22,Settings!$P$7:$P$10,0),MATCH(C22,Settings!$Q$6:$T$6,0)),"") | H22: =IF(OR(A22="",$B$8=""),"",$B$8) | I22: =IF(OR(A22="",$B$9=""),"",$B$9) | J22: =IF(OR(A22="",IF(H22="",$B$8,H22)="",IF(I22="",$B$9,I22)=""),"",IFERROR(NETWORKDAYS(IF(H22="",$B$8,H22),IF(I22="",$B$9,I22),INDEX(Settings!$J$7:$M$60,0,MATCH(C22,Settings!$J$6:$M$6,0))),NETWORKDAYS(IF(H22="",$B$8,H22),IF(I22="",$B$9,I22)))) | L22: =IF(C22="",0,IFERROR(INDEX(Settings!$B$6:$B$9,MATCH(C22,Settings!$A$6:$A$9,0)),0)) -> 0 | M22: =IF(OR(E22="",F22=""),0,E22*F22) -> 0 | N22: =IF(OR(E22="",G22=""),0,E22*G22) -> 0 | O22: =N22*L22 -> 0 | P22: =N22+O22 -> 0 | Q22: =IF(C22="",0,IFERROR(INDEX(Settings!$C$6:$C$9,MATCH(C22,Settings!$A$6:$A$9,0)),0)) -> 0 | S22: Labour by location
E23: =IF(K23<>"",K23,IF(J23="","",J23*Settings!$B$3*IF(D23="",1,D23))) | G23: =IFERROR(INDEX(Settings!$Q$7:$T$10,MATCH(B23,Settings!$P$7:$P$10,0),MATCH(C23,Settings!$Q$6:$T$6,0)),"") | H23: =IF(OR(A23="",$B$8=""),"",$B$8) | I23: =IF(OR(A23="",$B$9=""),"",$B$9) | J23: =IF(OR(A23="",IF(H23="",$B$8,H23)="",IF(I23="",$B$9,I23)=""),"",IFERROR(NETWORKDAYS(IF(H23="",$B$8,H23),IF(I23="",$B$9,I23),INDEX(Settings!$J$7:$M$60,0,MATCH(C23,Settings!$J$6:$M$6,0))),NETWORKDAYS(IF(H23="",$B$8,H23),IF(I23="",$B$9,I23)))) | L23: =IF(C23="",0,IFERROR(INDEX(Settings!$B$6:$B$9,MATCH(C23,Settings!$A$6:$A$9,0)),0)) -> 0 | M23: =IF(OR(E23="",F23=""),0,E23*F23) -> 0 | N23: =IF(OR(E23="",G23=""),0,E23*G23) -> 0 | O23: =N23*L23 -> 0 | P23: =N23+O23 -> 0 | Q23: =IF(C23="",0,IFERROR(INDEX(Settings!$C$6:$C$9,MATCH(C23,Settings!$A$6:$A$9,0)),0)) -> 0 | S23: Location | T23: Loaded cost | U23: Share of labour | V23: Floor
E24: =IF(K24<>"",K24,IF(J24="","",J24*Settings!$B$3*IF(D24="",1,D24))) | G24: =IFERROR(INDEX(Settings!$Q$7:$T$10,MATCH(B24,Settings!$P$7:$P$10,0),MATCH(C24,Settings!$Q$6:$T$6,0)),"") | H24: =IF(OR(A24="",$B$8=""),"",$B$8) | I24: =IF(OR(A24="",$B$9=""),"",$B$9) | J24: =IF(OR(A24="",IF(H24="",$B$8,H24)="",IF(I24="",$B$9,I24)=""),"",IFERROR(NETWORKDAYS(IF(H24="",$B$8,H24),IF(I24="",$B$9,I24),INDEX(Settings!$J$7:$M$60,0,MATCH(C24,Settings!$J$6:$M$6,0))),NETWORKDAYS(IF(H24="",$B$8,H24),IF(I24="",$B$9,I24)))) | L24: =IF(C24="",0,IFERROR(INDEX(Settings!$B$6:$B$9,MATCH(C24,Settings!$A$6:$A$9,0)),0)) -> 0 | M24: =IF(OR(E24="",F24=""),0,E24*F24) -> 0 | N24: =IF(OR(E24="",G24=""),0,E24*G24) -> 0 | O24: =N24*L24 -> 0 | P24: =N24+O24 -> 0 | Q24: =IF(C24="",0,IFERROR(INDEX(Settings!$C$6:$C$9,MATCH(C24,Settings!$A$6:$A$9,0)),0)) -> 0 | S24: =IF(Settings!A6="","",Settings!A6) -> US | T24: =IF(S24="","",SUMIF($C$17:$C$36,S24,$P$17:$P$36)) -> 30559.205 | U24: =IF(OR(S24="",$P$37=0),"",T24/$P$37) -> 1 | V24: =IF(S24="","",Settings!C6) -> 0.35
E25: =IF(K25<>"",K25,IF(J25="","",J25*Settings!$B$3*IF(D25="",1,D25))) | G25: =IFERROR(INDEX(Settings!$Q$7:$T$10,MATCH(B25,Settings!$P$7:$P$10,0),MATCH(C25,Settings!$Q$6:$T$6,0)),"") | H25: =IF(OR(A25="",$B$8=""),"",$B$8) | I25: =IF(OR(A25="",$B$9=""),"",$B$9) | J25: =IF(OR(A25="",IF(H25="",$B$8,H25)="",IF(I25="",$B$9,I25)=""),"",IFERROR(NETWORKDAYS(IF(H25="",$B$8,H25),IF(I25="",$B$9,I25),INDEX(Settings!$J$7:$M$60,0,MATCH(C25,Settings!$J$6:$M$6,0))),NETWORKDAYS(IF(H25="",$B$8,H25),IF(I25="",$B$9,I25)))) | L25: =IF(C25="",0,IFERROR(INDEX(Settings!$B$6:$B$9,MATCH(C25,Settings!$A$6:$A$9,0)),0)) -> 0 | M25: =IF(OR(E25="",F25=""),0,E25*F25) -> 0 | N25: =IF(OR(E25="",G25=""),0,E25*G25) -> 0 | O25: =N25*L25 -> 0 | P25: =N25+O25 -> 0 | Q25: =IF(C25="",0,IFERROR(INDEX(Settings!$C$6:$C$9,MATCH(C25,Settings!$A$6:$A$9,0)),0)) -> 0 | S25: =IF(Settings!A7="","",Settings!A7) -> India | T25: =IF(S25="","",SUMIF($C$17:$C$36,S25,$P$17:$P$36)) -> 0 | U25: =IF(OR(S25="",$P$37=0),"",T25/$P$37) -> 0 | V25: =IF(S25="","",Settings!C7) -> 0.5
E26: =IF(K26<>"",K26,IF(J26="","",J26*Settings!$B$3*IF(D26="",1,D26))) | G26: =IFERROR(INDEX(Settings!$Q$7:$T$10,MATCH(B26,Settings!$P$7:$P$10,0),MATCH(C26,Settings!$Q$6:$T$6,0)),"") | H26: =IF(OR(A26="",$B$8=""),"",$B$8) | I26: =IF(OR(A26="",$B$9=""),"",$B$9) | J26: =IF(OR(A26="",IF(H26="",$B$8,H26)="",IF(I26="",$B$9,I26)=""),"",IFERROR(NETWORKDAYS(IF(H26="",$B$8,H26),IF(I26="",$B$9,I26),INDEX(Settings!$J$7:$M$60,0,MATCH(C26,Settings!$J$6:$M$6,0))),NETWORKDAYS(IF(H26="",$B$8,H26),IF(I26="",$B$9,I26)))) | L26: =IF(C26="",0,IFERROR(INDEX(Settings!$B$6:$B$9,MATCH(C26,Settings!$A$6:$A$9,0)),0)) -> 0 | M26: =IF(OR(E26="",F26=""),0,E26*F26) -> 0 | N26: =IF(OR(E26="",G26=""),0,E26*G26) -> 0 | O26: =N26*L26 -> 0 | P26: =N26+O26 -> 0 | Q26: =IF(C26="",0,IFERROR(INDEX(Settings!$C$6:$C$9,MATCH(C26,Settings!$A$6:$A$9,0)),0)) -> 0 | S26: =IF(Settings!A8="","",Settings!A8) | T26: =IF(S26="","",SUMIF($C$17:$C$36,S26,$P$17:$P$36)) | U26: =IF(OR(S26="",$P$37=0),"",T26/$P$37) | V26: =IF(S26="","",Settings!C8)
E27: =IF(K27<>"",K27,IF(J27="","",J27*Settings!$B$3*IF(D27="",1,D27))) | G27: =IFERROR(INDEX(Settings!$Q$7:$T$10,MATCH(B27,Settings!$P$7:$P$10,0),MATCH(C27,Settings!$Q$6:$T$6,0)),"") | H27: =IF(OR(A27="",$B$8=""),"",$B$8) | I27: =IF(OR(A27="",$B$9=""),"",$B$9) | J27: =IF(OR(A27="",IF(H27="",$B$8,H27)="",IF(I27="",$B$9,I27)=""),"",IFERROR(NETWORKDAYS(IF(H27="",$B$8,H27),IF(I27="",$B$9,I27),INDEX(Settings!$J$7:$M$60,0,MATCH(C27,Settings!$J$6:$M$6,0))),NETWORKDAYS(IF(H27="",$B$8,H27),IF(I27="",$B$9,I27)))) | L27: =IF(C27="",0,IFERROR(INDEX(Settings!$B$6:$B$9,MATCH(C27,Settings!$A$6:$A$9,0)),0)) -> 0 | M27: =IF(OR(E27="",F27=""),0,E27*F27) -> 0 | N27: =IF(OR(E27="",G27=""),0,E27*G27) -> 0 | O27: =N27*L27 -> 0 | P27: =N27+O27 -> 0 | Q27: =IF(C27="",0,IFERROR(INDEX(Settings!$C$6:$C$9,MATCH(C27,Settings!$A$6:$A$9,0)),0)) -> 0 | S27: =IF(Settings!A9="","",Settings!A9) | T27: =IF(S27="","",SUMIF($C$17:$C$36,S27,$P$17:$P$36)) | U27: =IF(OR(S27="",$P$37=0),"",T27/$P$37) | V27: =IF(S27="","",Settings!C9)
E28: =IF(K28<>"",K28,IF(J28="","",J28*Settings!$B$3*IF(D28="",1,D28))) | G28: =IFERROR(INDEX(Settings!$Q$7:$T$10,MATCH(B28,Settings!$P$7:$P$10,0),MATCH(C28,Settings!$Q$6:$T$6,0)),"") | H28: =IF(OR(A28="",$B$8=""),"",$B$8) | I28: =IF(OR(A28="",$B$9=""),"",$B$9) | J28: =IF(OR(A28="",IF(H28="",$B$8,H28)="",IF(I28="",$B$9,I28)=""),"",IFERROR(NETWORKDAYS(IF(H28="",$B$8,H28),IF(I28="",$B$9,I28),INDEX(Settings!$J$7:$M$60,0,MATCH(C28,Settings!$J$6:$M$6,0))),NETWORKDAYS(IF(H28="",$B$8,H28),IF(I28="",$B$9,I28)))) | L28: =IF(C28="",0,IFERROR(INDEX(Settings!$B$6:$B$9,MATCH(C28,Settings!$A$6:$A$9,0)),0)) -> 0 | M28: =IF(OR(E28="",F28=""),0,E28*F28) -> 0 | N28: =IF(OR(E28="",G28=""),0,E28*G28) -> 0 | O28: =N28*L28 -> 0 | P28: =N28+O28 -> 0 | Q28: =IF(C28="",0,IFERROR(INDEX(Settings!$C$6:$C$9,MATCH(C28,Settings!$A$6:$A$9,0)),0)) -> 0
E29: =IF(K29<>"",K29,IF(J29="","",J29*Settings!$B$3*IF(D29="",1,D29))) | G29: =IFERROR(INDEX(Settings!$Q$7:$T$10,MATCH(B29,Settings!$P$7:$P$10,0),MATCH(C29,Settings!$Q$6:$T$6,0)),"") | H29: =IF(OR(A29="",$B$8=""),"",$B$8) | I29: =IF(OR(A29="",$B$9=""),"",$B$9) | J29: =IF(OR(A29="",IF(H29="",$B$8,H29)="",IF(I29="",$B$9,I29)=""),"",IFERROR(NETWORKDAYS(IF(H29="",$B$8,H29),IF(I29="",$B$9,I29),INDEX(Settings!$J$7:$M$60,0,MATCH(C29,Settings!$J$6:$M$6,0))),NETWORKDAYS(IF(H29="",$B$8,H29),IF(I29="",$B$9,I29)))) | L29: =IF(C29="",0,IFERROR(INDEX(Settings!$B$6:$B$9,MATCH(C29,Settings!$A$6:$A$9,0)),0)) -> 0 | M29: =IF(OR(E29="",F29=""),0,E29*F29) -> 0 | N29: =IF(OR(E29="",G29=""),0,E29*G29) -> 0 | O29: =N29*L29 -> 0 | P29: =N29+O29 -> 0 | Q29: =IF(C29="",0,IFERROR(INDEX(Settings!$C$6:$C$9,MATCH(C29,Settings!$A$6:$A$9,0)),0)) -> 0
E30: =IF(K30<>"",K30,IF(J30="","",J30*Settings!$B$3*IF(D30="",1,D30))) | G30: =IFERROR(INDEX(Settings!$Q$7:$T$10,MATCH(B30,Settings!$P$7:$P$10,0),MATCH(C30,Settings!$Q$6:$T$6,0)),"") | H30: =IF(OR(A30="",$B$8=""),"",$B$8) | I30: =IF(OR(A30="",$B$9=""),"",$B$9) | J30: =IF(OR(A30="",IF(H30="",$B$8,H30)="",IF(I30="",$B$9,I30)=""),"",IFERROR(NETWORKDAYS(IF(H30="",$B$8,H30),IF(I30="",$B$9,I30),INDEX(Settings!$J$7:$M$60,0,MATCH(C30,Settings!$J$6:$M$6,0))),NETWORKDAYS(IF(H30="",$B$8,H30),IF(I30="",$B$9,I30)))) | L30: =IF(C30="",0,IFERROR(INDEX(Settings!$B$6:$B$9,MATCH(C30,Settings!$A$6:$A$9,0)),0)) -> 0 | M30: =IF(OR(E30="",F30=""),0,E30*F30) -> 0 | N30: =IF(OR(E30="",G30=""),0,E30*G30) -> 0 | O30: =N30*L30 -> 0 | P30: =N30+O30 -> 0 | Q30: =IF(C30="",0,IFERROR(INDEX(Settings!$C$6:$C$9,MATCH(C30,Settings!$A$6:$A$9,0)),0)) -> 0 | S30: How to use
E31: =IF(K31<>"",K31,IF(J31="","",J31*Settings!$B$3*IF(D31="",1,D31))) | G31: =IFERROR(INDEX(Settings!$Q$7:$T$10,MATCH(B31,Settings!$P$7:$P$10,0),MATCH(C31,Settings!$Q$6:$T$6,0)),"") | H31: =IF(OR(A31="",$B$8=""),"",$B$8) | I31: =IF(OR(A31="",$B$9=""),"",$B$9) | J31: =IF(OR(A31="",IF(H31="",$B$8,H31)="",IF(I31="",$B$9,I31)=""),"",IFERROR(NETWORKDAYS(IF(H31="",$B$8,H31),IF(I31="",$B$9,I31),INDEX(Settings!$J$7:$M$60,0,MATCH(C31,Settings!$J$6:$M$6,0))),NETWORKDAYS(IF(H31="",$B$8,H31),IF(I31="",$B$9,I31)))) | L31: =IF(C31="",0,IFERROR(INDEX(Settings!$B$6:$B$9,MATCH(C31,Settings!$A$6:$A$9,0)),0)) -> 0 | M31: =IF(OR(E31="",F31=""),0,E31*F31) -> 0 | N31: =IF(OR(E31="",G31=""),0,E31*G31) -> 0 | O31: =N31*L31 -> 0 | P31: =N31+O31 -> 0 | Q31: =IF(C31="",0,IFERROR(INDEX(Settings!$C$6:$C$9,MATCH(C31,Settings!$A$6:$A$9,0)),0)) -> 0 | S31: 1. Fill the project block: engagement type, dates, and the price (Fixed cost / Assessment) or monthly fee (MSP). Duration is exact — Sep 7 to Oct 5 is 0.97 months (0 months 29 days). Partial months count by their days, so MSP fees and monthly costs are prorated.
E32: =IF(K32<>"",K32,IF(J32="","",J32*Settings!$B$3*IF(D32="",1,D32))) | G32: =IFERROR(INDEX(Settings!$Q$7:$T$10,MATCH(B32,Settings!$P$7:$P$10,0),MATCH(C32,Settings!$Q$6:$T$6,0)),"") | H32: =IF(OR(A32="",$B$8=""),"",$B$8) | I32: =IF(OR(A32="",$B$9=""),"",$B$9) | J32: =IF(OR(A32="",IF(H32="",$B$8,H32)="",IF(I32="",$B$9,I32)=""),"",IFERROR(NETWORKDAYS(IF(H32="",$B$8,H32),IF(I32="",$B$9,I32),INDEX(Settings!$J$7:$M$60,0,MATCH(C32,Settings!$J$6:$M$6,0))),NETWORKDAYS(IF(H32="",$B$8,H32),IF(I32="",$B$9,I32)))) | L32: =IF(C32="",0,IFERROR(INDEX(Settings!$B$6:$B$9,MATCH(C32,Settings!$A$6:$A$9,0)),0)) -> 0 | M32: =IF(OR(E32="",F32=""),0,E32*F32) -> 0 | N32: =IF(OR(E32="",G32=""),0,E32*G32) -> 0 | O32: =N32*L32 -> 0 | P32: =N32+O32 -> 0 | Q32: =IF(C32="",0,IFERROR(INDEX(Settings!$C$6:$C$9,MATCH(C32,Settings!$A$6:$A$9,0)),0)) -> 0 | S32: 2. Say Y or N to additional costs. If Y, every cost row needs Frequency and Billed-to-client — the Check column tells you.
E33: =IF(K33<>"",K33,IF(J33="","",J33*Settings!$B$3*IF(D33="",1,D33))) | G33: =IFERROR(INDEX(Settings!$Q$7:$T$10,MATCH(B33,Settings!$P$7:$P$10,0),MATCH(C33,Settings!$Q$6:$T$6,0)),"") | H33: =IF(OR(A33="",$B$8=""),"",$B$8) | I33: =IF(OR(A33="",$B$9=""),"",$B$9) | J33: =IF(OR(A33="",IF(H33="",$B$8,H33)="",IF(I33="",$B$9,I33)=""),"",IFERROR(NETWORKDAYS(IF(H33="",$B$8,H33),IF(I33="",$B$9,I33),INDEX(Settings!$J$7:$M$60,0,MATCH(C33,Settings!$J$6:$M$6,0))),NETWORKDAYS(IF(H33="",$B$8,H33),IF(I33="",$B$9,I33)))) | L33: =IF(C33="",0,IFERROR(INDEX(Settings!$B$6:$B$9,MATCH(C33,Settings!$A$6:$A$9,0)),0)) -> 0 | M33: =IF(OR(E33="",F33=""),0,E33*F33) -> 0 | N33: =IF(OR(E33="",G33=""),0,E33*G33) -> 0 | O33: =N33*L33 -> 0 | P33: =N33+O33 -> 0 | Q33: =IF(C33="",0,IFERROR(INDEX(Settings!$C$6:$C$9,MATCH(C33,Settings!$A$6:$A$9,0)),0)) -> 0 | S33: 3. One staffing row per person. Hours come from the dates (weekends and the location's holidays removed) × hours/day × utilization; type an override if the SOW fixes hours.
E34: =IF(K34<>"",K34,IF(J34="","",J34*Settings!$B$3*IF(D34="",1,D34))) | G34: =IFERROR(INDEX(Settings!$Q$7:$T$10,MATCH(B34,Settings!$P$7:$P$10,0),MATCH(C34,Settings!$Q$6:$T$6,0)),"") | H34: =IF(OR(A34="",$B$8=""),"",$B$8) | I34: =IF(OR(A34="",$B$9=""),"",$B$9) | J34: =IF(OR(A34="",IF(H34="",$B$8,H34)="",IF(I34="",$B$9,I34)=""),"",IFERROR(NETWORKDAYS(IF(H34="",$B$8,H34),IF(I34="",$B$9,I34),INDEX(Settings!$J$7:$M$60,0,MATCH(C34,Settings!$J$6:$M$6,0))),NETWORKDAYS(IF(H34="",$B$8,H34),IF(I34="",$B$9,I34)))) | L34: =IF(C34="",0,IFERROR(INDEX(Settings!$B$6:$B$9,MATCH(C34,Settings!$A$6:$A$9,0)),0)) -> 0 | M34: =IF(OR(E34="",F34=""),0,E34*F34) -> 0 | N34: =IF(OR(E34="",G34=""),0,E34*G34) -> 0 | O34: =N34*L34 -> 0 | P34: =N34+O34 -> 0 | Q34: =IF(C34="",0,IFERROR(INDEX(Settings!$C$6:$C$9,MATCH(C34,Settings!$A$6:$A$9,0)),0)) -> 0 | S34: 4. Bill rate matters only for Time & materials. For Fixed cost, Assessment and MSP the revenue is the price or fee, not the hours.
E35: =IF(K35<>"",K35,IF(J35="","",J35*Settings!$B$3*IF(D35="",1,D35))) | G35: =IFERROR(INDEX(Settings!$Q$7:$T$10,MATCH(B35,Settings!$P$7:$P$10,0),MATCH(C35,Settings!$Q$6:$T$6,0)),"") | H35: =IF(OR(A35="",$B$8=""),"",$B$8) | I35: =IF(OR(A35="",$B$9=""),"",$B$9) | J35: =IF(OR(A35="",IF(H35="",$B$8,H35)="",IF(I35="",$B$9,I35)=""),"",IFERROR(NETWORKDAYS(IF(H35="",$B$8,H35),IF(I35="",$B$9,I35),INDEX(Settings!$J$7:$M$60,0,MATCH(C35,Settings!$J$6:$M$6,0))),NETWORKDAYS(IF(H35="",$B$8,H35),IF(I35="",$B$9,I35)))) | L35: =IF(C35="",0,IFERROR(INDEX(Settings!$B$6:$B$9,MATCH(C35,Settings!$A$6:$A$9,0)),0)) -> 0 | M35: =IF(OR(E35="",F35=""),0,E35*F35) -> 0 | N35: =IF(OR(E35="",G35=""),0,E35*G35) -> 0 | O35: =N35*L35 -> 0 | P35: =N35+O35 -> 0 | Q35: =IF(C35="",0,IFERROR(INDEX(Settings!$C$6:$C$9,MATCH(C35,Settings!$A$6:$A$9,0)),0)) -> 0 | S35: 5. GM % = (revenue − labour − burden − additional costs) ÷ revenue, checked against the floor blended by labour cost share.
E36: =IF(K36<>"",K36,IF(J36="","",J36*Settings!$B$3*IF(D36="",1,D36))) | G36: =IFERROR(INDEX(Settings!$Q$7:$T$10,MATCH(B36,Settings!$P$7:$P$10,0),MATCH(C36,Settings!$Q$6:$T$6,0)),"") | H36: =IF(OR(A36="",$B$8=""),"",$B$8) | I36: =IF(OR(A36="",$B$9=""),"",$B$9) | J36: =IF(OR(A36="",IF(H36="",$B$8,H36)="",IF(I36="",$B$9,I36)=""),"",IFERROR(NETWORKDAYS(IF(H36="",$B$8,H36),IF(I36="",$B$9,I36),INDEX(Settings!$J$7:$M$60,0,MATCH(C36,Settings!$J$6:$M$6,0))),NETWORKDAYS(IF(H36="",$B$8,H36),IF(I36="",$B$9,I36)))) | L36: =IF(C36="",0,IFERROR(INDEX(Settings!$B$6:$B$9,MATCH(C36,Settings!$A$6:$A$9,0)),0)) -> 0 | M36: =IF(OR(E36="",F36=""),0,E36*F36) -> 0 | N36: =IF(OR(E36="",G36=""),0,E36*G36) -> 0 | O36: =N36*L36 -> 0 | P36: =N36+O36 -> 0 | Q36: =IF(C36="",0,IFERROR(INDEX(Settings!$C$6:$C$9,MATCH(C36,Settings!$A$6:$A$9,0)),0)) -> 0 | S36: 6. Monthly tab: people on the project, cost and margin for every month of the tenure — read it for MSP.
A37: Staffing total | E37: =SUM(E17:E36) -> 208.32 | M37: =SUM(M17:M36) -> 0 | N37: =SUM(N17:N36) -> 27416.122 | O37: =SUM(O17:O36) -> 3143.0838 | P37: =SUM(P17:P36) -> 30559.205 | S37: 7. Leave a person's Start/End blank to use the project dates; fill them only if someone joins late or leaves early.
S38: 8. Sheets are unprotected while the form is being stabilised. Don't delete rows inside the staffing table — the Monthly tab maps to them; clear a row's yellow cells instead.
A39: Additional costs — travel, meals, licences, hardware, subcontractors (required when B13 = Y). To remove one, clear its yellow cells. | S39: 9. The sheet starts empty on purpose. Settings has placeholder burden % — set your real values once.
A40: Description * | B40: Category * | C40: Location | D40: Amount * | E40: Frequency (dropdown: One-time or Monthly; blank = One-time) | F40: Billed to client? * (dropdown Y/N — required) | G40: Total cost counted | H40: Revenue counted (pass-through) | I40: Check
...

Sheet Monthly
A1: Month by month — people, cost and margin
A2: Built from the Cost Margin tab. Up to 24 months. Partial first/last months are prorated by days (row 4). MSP revenue = monthly fee × share of month; Fixed cost / Assessment = price spread by share of month; T&M = that month's hours × bill rate. One-time additional costs land in month 1; monthly ones repeat, prorated.
A3: =IF('Cost Margin'!$B$10="","Fill engagement type and project dates on the Cost Margin tab.",IF('Cost Margin'!$B$10>2,"Monthly view REQUIRED — this engagement runs "&TEXT('Cost Margin'!$B$10,"0.0")&" months.","Not needed — this engagement is "&TEXT('Cost Margin'!$B$10,"0.0")&" month(s). Use the Cost Margin summary; everything below is greyed out.")) -> Not needed — this engagement is 1.0 month(s). Use the Cost Margin summary; everything below is greyed out.
A4: Share of month covered | C4: =IF(C5="","",(C6-C5+1)/DAY(EOMONTH(C5,0))) -> 0.8 | D4: =IF(D5="","",(D6-D5+1)/DAY(EOMONTH(D5,0))) -> 0.16129032 | E4: =IF(E5="","",(E6-E5+1)/DAY(EOMONTH(E5,0))) | F4: =IF(F5="","",(F6-F5+1)/DAY(EOMONTH(F5,0))) | G4: =IF(G5="","",(G6-G5+1)/DAY(EOMONTH(G5,0))) | H4: =IF(H5="","",(H6-H5+1)/DAY(EOMONTH(H5,0))) | I4: =IF(I5="","",(I6-I5+1)/DAY(EOMONTH(I5,0))) | J4: =IF(J5="","",(J6-J5+1)/DAY(EOMONTH(J5,0))) | ... Z4: =IF(Z5="","",(Z6-Z5+1)/DAY(EOMONTH(Z5,0)))
A5: Month start | B5: =IF(OR('Cost Margin'!$B$8="",'Cost Margin'!$B$9=""),"",(YEAR('Cost Margin'!$B$9)-YEAR('Cost Margin'!$B$8))*12+MONTH('Cost Margin'!$B$9)-MONTH('Cost Margin'!$B$8)+1) -> 2 | C5: =IF('Cost Margin'!$B$8="","",'Cost Margin'!$B$8) -> 46272 | D5: =IF(OR($C$5="",$B$5="",1>=$B$5),"",EOMONTH($C$5,0)+1) -> 46296 | E5: =IF(OR($C$5="",$B$5="",2>=$B$5),"",EOMONTH($C$5,1)+1) | F5: =IF(OR($C$5="",$B$5="",3>=$B$5),"",EOMONTH($C$5,2)+1) | G5: =IF(OR($C$5="",$B$5="",4>=$B$5),"",EOMONTH($C$5,3)+1) | H5: =IF(OR($C$5="",$B$5="",5>=$B$5),"",EOMONTH($C$5,4)+1) | I5: =IF(OR($C$5="",$B$5="",6>=$B$5),"",EOMONTH($C$5,5)+1) | J5: =IF(OR($C$5="",$B$5="",7>=$B$5),"",EOMONTH($C$5,6)+1) | K5: =IF(OR($C$5="",$B$5="",8>=$B$5),"",EOMONTH($C$5,7)+1) | L5: =IF(OR($C$5="",$B$5="",9>=$B$5),"",EOMONTH($C$5,8)+1) | M5: =IF(OR($C$5="",$B$5="",10>=$B$5),"",EOMONTH($C$5,9)+1) | N5: =IF(OR($C$5="",$B$5="",11>=$B$5),"",EOMONTH($C$5,10)+1) | O5: =IF(OR($C$5="",$B$5="",12>=$B$5),"",EOMONTH($C$5,11)+1) | P5: =IF(OR($C$5="",$B$5="",13>=$B$5),"",EOMONTH($C$5,12)+1) | Q5: =IF(OR($C$5="",$B$5="",14>=$B$5),"",EOMONTH($C$5,13)+1) | R5: =IF(OR($C$5="",$B$5="",15>=$B$5),"",EOMONTH($C$5,14)+1) | S5: =IF(OR($C$5="",$B$5="",16>=$B$5),"",EOMONTH($C$5,15)+1) | T5: =IF(OR($C$5="",$B$5="",17>=$B$5),"",EOMONTH($C$5,16)+1) | U5: =IF(OR($C$5="",$B$5="",18>=$B$5),"",EOMONTH($C$5,17)+1) | V5: =IF(OR($C$5="",$B$5="",19>=$B$5),"",EOMONTH($C$5,18)+1) | W5: =IF(OR($C$5="",$B$5="",20>=$B$5),"",EOMONTH($C$5,19)+1) | X5: =IF(OR($C$5="",$B$5="",21>=$B$5),"",EOMONTH($C$5,20)+1) | Y5: =IF(OR($C$5="",$B$5="",22>=$B$5),"",EOMONTH($C$5,21)+1) | Z5: =IF(OR($C$5="",$B$5="",23>=$B$5),"",EOMONTH($C$5,22)+1)
A6: Month end | B6: ← calendar months in view | C6: =IF(C5="","",MIN(EOMONTH(C5,0),'Cost Margin'!$B$9)) -> 46295 | D6: =IF(D5="","",MIN(EOMONTH(D5,0),'Cost Margin'!$B$9)) -> 46300 | E6: =IF(E5="","",MIN(EOMONTH(E5,0),'Cost Margin'!$B$9)) | F6: =IF(F5="","",MIN(EOMONTH(F5,0),'Cost Margin'!$B$9)) | G6: =IF(G5="","",MIN(EOMONTH(G5,0),'Cost Margin'!$B$9)) | H6: =IF(H5="","",MIN(EOMONTH(H5,0),'Cost Margin'!$B$9)) | I6: =IF(I5="","",MIN(EOMONTH(I5,0),'Cost Margin'!$B$9)) | J6: =IF(J5="","",MIN(EOMONTH(J5,0),'Cost Margin'!$B$9)) | ... Z6: =IF(Z5="","",MIN(EOMONTH(Z5,0),'Cost Margin'!$B$9))
A7: Row | B7: Person / line | C7: =IF(C5="","",TEXT(C5,"mmm yyyy")) -> Sep 2026 | D7: =IF(D5="","",TEXT(D5,"mmm yyyy")) -> Oct 2026 | E7: =IF(E5="","",TEXT(E5,"mmm yyyy")) | F7: =IF(F5="","",TEXT(F5,"mmm yyyy")) | G7: =IF(G5="","",TEXT(G5,"mmm yyyy")) | H7: =IF(H5="","",TEXT(H5,"mmm yyyy")) | I7: =IF(I5="","",TEXT(I5,"mmm yyyy")) | J7: =IF(J5="","",TEXT(J5,"mmm yyyy")) | ... Z7: =IF(Z5="","",TEXT(Z5,"mmm yyyy")) | AA7: Project total
A8: Working days in month, per person
A9: 1 | B9: =IF('Cost Margin'!A17="","",'Cost Margin'!A17) -> Vikrin | C9: =IF(OR(C$5="",'Cost Margin'!$A17="",IF('Cost Margin'!$H17="",'Cost Margin'!$B$8,'Cost Margin'!$H17)="",IF('Cost Margin'!$I17="",'Cost Margin'!$B$9,'Cost Margin'!$I17)=""),0,IF(MIN(IF('Cost Margin'!$I17="",'Cost Margin'!$B$9,'Cost Margin'!$I17),C$6)<MAX(IF('Cost Margin'!$H17="",'Cost Margin'!$B$8,'Cost Margin'!$H17),C$5),0,IFERROR(NETWORKDAYS(MAX(IF('Cost Margin'!$H17="",'Cost Margin'!$B$8,'Cost Margin'!$H17),C$5),MIN(IF('Cost Margin'!$I17="",'Cost Margin'!$B$9,'Cost Margin'!$I17),C$6),INDEX(Settings!$J$7:$M$60,0,MATCH('Cost Margin'!$C17,Settings!$J$6:$M$6,0))),NETWORKDAYS(MAX(IF('Cost Margin'!$H17="",'Cost Margin'!$B$8,'Cost Margin'!$H17),C$5),MIN(IF('Cost Margin'!$I17="",'Cost Margin'!$B$9,'Cost Margin'!$I17),C$6))))) -> 18 | D9: =IF(OR(D$5="",'Cost Margin'!$A17="",IF('Cost Margin'!$H17="",'Cost Margin'!$B$8,'Cost Margin'!$H17)="",IF('Cost Margin'!$I17="",'Cost Margin'!$B$9,'Cost Margin'!$I17)=""),0,IF(MIN(IF('Cost Margin'!$I17="",'Cost Margin'!$B$9,'Cost Margin'!$I17),D$6)<MAX(IF('Cost Margin'!$H17="",'Cost Margin'!$B$8,'Cost Margin'!$H17),D$5),0,IFERROR(NETWORKDAYS(MAX(IF('Cost Margin'!$H17="",'Cost Margin'!$B$8,'Cost Margin'!$H17),D$5),MIN(IF('Cost Margin'!$I17="",'Cost Margin'!$B$9,'Cost Margin'!$I17),D$6),INDEX(Settings!$J$7:$M$60,0,MATCH('Cost Margin'!$C17,Settings!$J$6:$M$6,0))),NETWORKDAYS(MAX(IF('Cost Margin'!$H17="",'Cost Margin'!$B$8,'Cost Margin'!$H17),D$5),MIN(IF('Cost Margin'!$I17="",'Cost Margin'!$B$9,'Cost Margin'!$I17),D$6))))) -> 3 | E9: =IF(OR(E$5="",'Cost Margin'!$A17="",IF('Cost Margin'!$H17="",'Cost Margin'!$B$8,'Cost Margin'!$H17)="",IF('Cost Margin'!$I17="",'Cost Margin'!$B$9,'Cost Margin'!$I17)=""),0,IF(MIN(IF('Cost Margin'!$I17="",'Cost Margin'!$B$9,'Cost Margin'!$I17),E$6)<MAX(IF('Cost Margin'!$H17="",'Cost Margin'!$B$8,'Cost Margin'!$H17),E$5),0,IFERROR(NETWORKDAYS(MAX(IF('Cost Margin'!$H17="",'Cost Margin'!$B$8,'Cost Margin'!$H17),E$5),MIN(IF('Cost Margin'!$I17="",'Cost Margin'!$B$9,'Cost Margin'!$I17),E$6),INDEX(Settings!$J$7:$M$60,0,MATCH('Cost Margin'!$C17,Settings!$J$6:$M$6,0))),NETWORKDAYS(MAX(IF('Cost Margin'!$H17="",'Cost Margin'!$B$8,'Cost Margin'!$H17),E$5),MIN(IF('Cost Margin'!$I17="",'Cost Margin'!$B$9,'Cost Margin'!$I17),E$6))))) -> 0 | F9: =IF(OR(F$5="",'Cost Margin'!$A17="",IF('Cost Margin'!$H17="",'Cost Margin'!$B$8,'Cost Margin'!$H17)="",IF('Cost Margin'!$I17="",'Cost Margin'!$B$9,'Cost Margin'!$I17)=""),0,IF(MIN(IF('Cost Margin'!$I17="",'Cost Margin'!$B$9,'Cost Margin'!$I17),F$6)<MAX(IF('Cost Margin'!$H17="",'Cost Margin'!$B$8,'Cost Margin'!$H17),F$5),0,IFERROR(NETWORKDAYS(MAX(IF('Cost Margin'!$H17="",'Cost Margin'!$B$8,'Cost Margin'!$H17),F$5),MIN(IF('Cost Margin'!$I17="",'Cost Margin'!$B$9,'Cost Margin'!$I17),F$6),INDEX(Settings!$J$7:$M$60,0,MATCH('Cost Margin'!$C17,Settings!$J$6:$M$6,0))),NETWORKDAYS(MAX(IF('Cost Margin'!$H17="",'Cost Margin'!$B$8,'Cost Margin'!$H17),F$5),MIN(IF('Cost Margin'!$I17="",'Cost Margin'!$B$9,'Cost Margin'!$I17),F$6))))) -> 0 | G9: =IF(OR(G$5="",'Cost Margin'!$A17="",IF('Cost Margin'!$H17="",'Cost Margin'!$B$8,'Cost Margin'!$H17)="",IF('Cost Margin'!$I17="",'Cost Margin'!$B$9,'Cost Margin'!$I17)=""),0,IF(MIN(IF('Cost Margin'!$I17="",'Cost Margin'!$B$9,'Cost Margin'!$I17),G$6)<MAX(IF('Cost Margin'!$H17="",'Cost Margin'!$B$8,'Cost Margin'!$H17),G$5),0,IFERROR(NETWORKDAYS(MAX(IF('Cost Margin'!$H17="",'Cost Margin'!$B$8,'Cost Margin'!$H17),G$5),MIN(IF('Cost Margin'!$I17="",'Cost Margin'!$B$9,'Cost Margin'!$I17),G$6),INDEX(Settings!$J$7:$M$60,0,MATCH('Cost Margin'!$C17,Settings!$J$6:$M$6,0))),NETWORKDAYS(MAX(IF('Cost Margin'!$H17="",'Cost Margin'!$B$8,'Cost Margin'!$H17),G$5),MIN(IF('Cost Margin'!$I17="",'Cost Margin'!$B$9,'Cost Margin'!$I17),G$6))))) -> 0 | H9: =IF(OR(H$5="",'Cost Margin'!$A17="",IF('Cost Margin'!$H17="",'Cost Margin'!$B$8,'Cost Margin'!$H17)="",IF('Cost Margin'!$I17="",'Cost Margin'!$B$9,'Cost Margin'!$I17)=""),0,IF(MIN(IF('Cost Margin'!$I17="",'Cost Margin'!$B$9,'Cost Margin'!$I17),H$6)<MAX(IF('Cost Margin'!$H17="",'Cost Margin'!$B$8,'Cost Margin'!$H17),H$5),0,IFERROR(NETWORKDAYS(MAX(IF('Cost Margin'!$H17="",'Cost Margin'!$B$8,'Cost Margin'!$H17),H$5),MIN(IF('Cost Margin'!$I17="",'Cost Margin'!$B$9,'Cost Margin'!$I17),H$6),INDEX(Settings!$J$7:$M$60,0,MATCH('Cost Margin'!$C17,Settings!$J$6:$M$6,0))),NETWORKDAYS(MAX(IF('Cost Margin'!$H17="",'Cost Margin'!$B$8,'Cost Margin'!$H17),H$5),MIN(IF('Cost Margin'!$I17="",'Cost Margin'!$B$9,'Cost Margin'!$I17),H$6))))) -> 0 | I9: =IF(OR(I$5="",'Cost Margin'!$A17="",IF('Cost Margin'!$H17="",'Cost Margin'!$B$8,'Cost Margin'!$H17)="",IF('Cost Margin'!$I17="",'Cost Margin'!$B$9,'Cost Margin'!$I17)=""),0,IF(MIN(IF('Cost Margin'!$I17="",'Cost Margin'!$B$9,'Cost Margin'!$I17),I$6)<MAX(IF('Cost Margin'!$H17="",'Cost Margin'!$B$8,'Cost Margin'!$H17),I$5),0,IFERROR(NETWORKDAYS(MAX(IF('Cost Margin'!$H17="",'Cost Margin'!$B$8,'Cost Margin'!$H17),I$5),MIN(IF('Cost Margin'!$I17="",'Cost Margin'!$B$9,'Cost Margin'!$I17),I$6),INDEX(Settings!$J$7:$M$60,0,MATCH('Cost Margin'!$C17,Settings!$J$6:$M$6,0))),NETWORKDAYS(MAX(IF('Cost Margin'!$H17="",'Cost Margin'!$B$8,'Cost Margin'!$H17),I$5),MIN(IF('Cost Margin'!$I17="",'Cost Margin'!$B$9,'Cost Margin'!$I17),I$6))))) -> 0 | J9: =IF(OR(J$5="",'Cost Margin'!$A17="",IF('Cost Margin'!$H17="",'Cost Margin'!$B$8,'Cost Margin'!$H17)="",IF('Cost Margin'!$I17="",'Cost Margin'!$B$9,'Cost Margin'!$I17)=""),0,IF(MIN(IF('Cost Margin'!$I17="",'Cost Margin'!$B$9,'Cost Margin'!$I17),J$6)<MAX(IF('Cost Margin'!$H17="",'Cost Margin'!$B$8,'Cost Margin'!$H17),J$5),0,IFERROR(NETWORKDAYS(MAX(IF('Cost Margin'!$H17="",'Cost Margin'!$B$8,'Cost Margin'!$H17),J$5),MIN(IF('Cost Margin'!$I17="",'Cost Margin'!$B$9,'Cost Margin'!$I17),J$6),INDEX(Settings!$J$7:$M$60,0,MATCH('Cost Margin'!$C17,Settings!$J$6:$M$6,0))),NETWORKDAYS(MAX(IF('Cost Margin'!$H17="",'Cost Margin'!$B$8,'Cost Margin'!$H17),J$5),MIN(IF('Cost Margin'!$I17="",'Cost Margin'!$B$9,'Cost Margin'!$I17),J$6))))) -> 0 | ... Z9: =IF(OR(Z$5="",'Cost Margin'!$A17="",IF('Cost Margin'!$H17="",'Cost Margin'!$B$8,'Cost Margin'!$H17)="",IF('Cost Margin'!$I17="",'Cost Margin'!$B$9,'Cost Margin'!$I17)=""),0,IF(MIN(IF('Cost Margin'!$I17="",'Cost Margin'!$B$9,'Cost Margin'!$I17),Z$6)<MAX(IF('Cost Margin'!$H17="",'Cost Margin'!$B$8,'Cost Margin'!$H17),Z$5),0,IFERROR(NETWORKDAYS(MAX(IF('Cost Margin'!$H17="",'Cost Margin'!$B$8,'Cost Margin'!$H17),Z$5),MIN(IF('Cost Margin'!$I17="",'Cost Margin'!$B$9,'Cost Margin'!$I17),Z$6),INDEX(Settings!$J$7:$M$60,0,MATCH('Cost Margin'!$C17,Settings!$J$6:$M$6,0))),NETWORKDAYS(MAX(IF('Cost Margin'!$H17="",'Cost Margin'!$B$8,'Cost Margin'!$H17),Z$5),MIN(IF('Cost Margin'!$I17="",'Cost Margin'!$B$9,'Cost Margin'!$I17),Z$6))))) -> 0
A10: 2 | B10: =IF('Cost Margin'!A18="","",'Cost Margin'!A18) -> srikanth | C10: =IF(OR(C$5="",'Cost Margin'!$A18="",IF('Cost Margin'!$H18="",'Cost Margin'!$B$8,'Cost Margin'!$H18)="",IF('Cost Margin'!$I18="",'Cost Margin'!$B$9,'Cost Margin'!$I18)=""),0,IF(MIN(IF('Cost Margin'!$I18="",'Cost Margin'!$B$9,'Cost Margin'!$I18),C$6)<MAX(IF('Cost Margin'!$H18="",'Cost Margin'!$B$8,'Cost Margin'!$H18),C$5),0,IFERROR(NETWORKDAYS(MAX(IF('Cost Margin'!$H18="",'Cost Margin'!$B$8,'Cost Margin'!$H18),C$5),MIN(IF('Cost Margin'!$I18="",'Cost Margin'!$B$9,'Cost Margin'!$I18),C$6),INDEX(Settings!$J$7:$M$60,0,MATCH('Cost Margin'!$C18,Settings!$J$6:$M$6,0))),NETWORKDAYS(MAX(IF('Cost Margin'!$H18="",'Cost Margin'!$B$8,'Cost Margin'!$H18),C$5),MIN(IF('Cost Margin'!$I18="",'Cost Margin'!$B$9,'Cost Margin'!$I18),C$6))))) -> 18 | D10: =IF(OR(D$5="",'Cost Margin'!$A18="",IF('Cost Margin'!$H18="",'Cost Margin'!$B$8,'Cost Margin'!$H18)="",IF('Cost Margin'!$I18="",'Cost Margin'!$B$9,'Cost Margin'!$I18)=""),0,IF(MIN(IF('Cost Margin'!$I18="",'Cost Margin'!$B$9,'Cost Margin'!$I18),D$6)<MAX(IF('Cost Margin'!$H18="",'Cost Margin'!$B$8,'Cost Margin'!$H18),D$5),0,IFERROR(NETWORKDAYS(MAX(IF('Cost Margin'!$H18="",'Cost Margin'!$B$8,'Cost Margin'!$H18),D$5),MIN(IF('Cost Margin'!$I18="",'Cost Margin'!$B$9,'Cost Margin'!$I18),D$6),INDEX(Settings!$J$7:$M$60,0,MATCH('Cost Margin'!$C18,Settings!$J$6:$M$6,0))),NETWORKDAYS(MAX(IF('Cost Margin'!$H18="",'Cost Margin'!$B$8,'Cost Margin'!$H18),D$5),MIN(IF('Cost Margin'!$I18="",'Cost Margin'!$B$9,'Cost Margin'!$I18),D$6))))) -> 3 | E10: =IF(OR(E$5="",'Cost Margin'!$A18="",IF('Cost Margin'!$H18="",'Cost Margin'!$B$8,'Cost Margin'!$H18)="",IF('Cost Margin'!$I18="",'Cost Margin'!$B$9,'Cost Margin'!$I18)=""),0,IF(MIN(IF('Cost Margin'!$I18="",'Cost Margin'!$B$9,'Cost Margin'!$I18),E$6)<MAX(IF('Cost Margin'!$H18="",'Cost Margin'!$B$8,'Cost Margin'!$H18),E$5),0,IFERROR(NETWORKDAYS(MAX(IF('Cost Margin'!$H18="",'Cost Margin'!$B$8,'Cost Margin'!$H18),E$5),MIN(IF('Cost Margin'!$I18="",'Cost Margin'!$B$9,'Cost Margin'!$I18),E$6),INDEX(Settings!$J$7:$M$60,0,MATCH('Cost Margin'!$C18,Settings!$J$6:$M$6,0))),NETWORKDAYS(MAX(IF('Cost Margin'!$H18="",'Cost Margin'!$B$8,'Cost Margin'!$H18),E$5),MIN(IF('Cost Margin'!$I18="",'Cost Margin'!$B$9,'Cost Margin'!$I18),E$6))))) -> 0 | F10: =IF(OR(F$5="",'Cost Margin'!$A18="",IF('Cost Margin'!$H18="",'Cost Margin'!$B$8,'Cost Margin'!$H18)="",IF('Cost Margin'!$I18="",'Cost Margin'!$B$9,'Cost Margin'!$I18)=""),0,IF(MIN(IF('Cost Margin'!$I18="",'Cost Margin'!$B$9,'Cost Margin'!$I18),F$6)<MAX(IF('Cost Margin'!$H18="",'Cost Margin'!$B$8,'Cost Margin'!$H18),F$5),0,IFERROR(NETWORKDAYS(MAX(IF('Cost Margin'!$H18="",'Cost Margin'!$B$8,'Cost Margin'!$H18),F$5),MIN(IF('Cost Margin'!$I18="",'Cost Margin'!$B$9,'Cost Margin'!$I18),F$6),INDEX(Settings!$J$7:$M$60,0,MATCH('Cost Margin'!$C18,Settings!$J$6:$M$6,0))),NETWORKDAYS(MAX(IF('Cost Margin'!$H18="",'Cost Margin'!$B$8,'Cost Margin'!$H18),F$5),MIN(IF('Cost Margin'!$I18="",'Cost Margin'!$B$9,'Cost Margin'!$I18),F$6))))) -> 0 | G10: =IF(OR(G$5="",'Cost Margin'!$A18="",IF('Cost Margin'!$H18="",'Cost Margin'!$B$8,'Cost Margin'!$H18)="",IF('Cost Margin'!$I18="",'Cost Margin'!$B$9,'Cost Margin'!$I18)=""),0,IF(MIN(IF('Cost Margin'!$I18="",'Cost Margin'!$B$9,'Cost Margin'!$I18),G$6)<MAX(IF('Cost Margin'!$H18="",'Cost Margin'!$B$8,'Cost Margin'!$H18),G$5),0,IFERROR(NETWORKDAYS(MAX(IF('Cost Margin'!$H18="",'Cost Margin'!$B$8,'Cost Margin'!$H18),G$5),MIN(IF('Cost Margin'!$I18="",'Cost Margin'!$B$9,'Cost Margin'!$I18),G$6),INDEX(Settings!$J$7:$M$60,0,MATCH('Cost Margin'!$C18,Settings!$J$6:$M$6,0))),NETWORKDAYS(MAX(IF('Cost Margin'!$H18="",'Cost Margin'!$B$8,'Cost Margin'!$H18),G$5),MIN(IF('Cost Margin'!$I18="",'Cost Margin'!$B$9,'Cost Margin'!$I18),G$6))))) -> 0 | H10: =IF(OR(H$5="",'Cost Margin'!$A18="",IF('Cost Margin'!$H18="",'Cost Margin'!$B$8,'Cost Margin'!$H18)="",IF('Cost Margin'!$I18="",'Cost Margin'!$B$9,'Cost Margin'!$I18)=""),0,IF(MIN(IF('Cost Margin'!$I18="",'Cost Margin'!$B$9,'Cost Margin'!$I18),H$6)<MAX(IF('Cost Margin'!$H18="",'Cost Margin'!$B$8,'Cost Margin'!$H18),H$5),0,IFERROR(NETWORKDAYS(MAX(IF('Cost Margin'!$H18="",'Cost Margin'!$B$8,'Cost Margin'!$H18),H$5),MIN(IF('Cost Margin'!$I18="",'Cost Margin'!$B$9,'Cost Margin'!$I18),H$6),INDEX(Settings!$J$7:$M$60,0,MATCH('Cost Margin'!$C18,Settings!$J$6:$M$6,0))),NETWORKDAYS(MAX(IF('Cost Margin'!$H18="",'Cost Margin'!$B$8,'Cost Margin'!$H18),H$5),MIN(IF('Cost Margin'!$I18="",'Cost Margin'!$B$9,'Cost Margin'!$I18),H$6))))) -> 0 | I10: =IF(OR(I$5="",'Cost Margin'!$A18="",IF('Cost Margin'!$H18="",'Cost Margin'!$B$8,'Cost Margin'!$H18)="",IF('Cost Margin'!$I18="",'Cost Margin'!$B$9,'Cost Margin'!$I18)=""),0,IF(MIN(IF('Cost Margin'!$I18="",'Cost Margin'!$B$9,'Cost Margin'!$I18),I$6)<MAX(IF('Cost Margin'!$H18="",'Cost Margin'!$B$8,'Cost Margin'!$H18),I$5),0,IFERROR(NETWORKDAYS(MAX(IF('Cost Margin'!$H18="",'Cost Margin'!$B$8,'Cost Margin'!$H18),I$5),MIN(IF('Cost Margin'!$I18="",'Cost Margin'!$B$9,'Cost Margin'!$I18),I$6),INDEX(Settings!$J$7:$M$60,0,MATCH('Cost Margin'!$C18,Settings!$J$6:$M$6,0))),NETWORKDAYS(MAX(IF('Cost Margin'!$H18="",'Cost Margin'!$B$8,'Cost Margin'!$H18),I$5),MIN(IF('Cost Margin'!$I18="",'Cost Margin'!$B$9,'Cost Margin'!$I18),I$6))))) -> 0 | J10: =IF(OR(J$5="",'Cost Margin'!$A18="",IF('Cost Margin'!$H18="",'Cost Margin'!$B$8,'Cost Margin'!$H18)="",IF('Cost Margin'!$I18="",'Cost Margin'!$B$9,'Cost Margin'!$I18)=""),0,IF(MIN(IF('Cost Margin'!$I18="",'Cost Margin'!$B$9,'Cost Margin'!$I18),J$6)<MAX(IF('Cost Margin'!$H18="",'Cost Margin'!$B$8,'Cost Margin'!$H18),J$5),0,IFERROR(NETWORKDAYS(MAX(IF('Cost Margin'!$H18="",'Cost Margin'!$B$8,'Cost Margin'!$H18),J$5),MIN(IF('Cost Margin'!$I18="",'Cost Margin'!$B$9,'Cost Margin'!$I18),J$6),INDEX(Settings!$J$7:$M$60,0,MATCH('Cost Margin'!$C18,Settings!$J$6:$M$6,0))),NETWORKDAYS(MAX(IF('Cost Margin'!$H18="",'Cost Margin'!$B$8,'Cost Margin'!$H18),J$5),MIN(IF('Cost Margin'!$I18="",'Cost Margin'!$B$9,'Cost Margin'!$I18),J$6))))) -> 0 | ... Z10: =IF(OR(Z$5="",'Cost Margin'!$A18="",IF('Cost Margin'!$H18="",'Cost Margin'!$B$8,'Cost Margin'!$H18)="",IF('Cost Margin'!$I18="",'Cost Margin'!$B$9,'Cost Margin'!$I18)=""),0,IF(MIN(IF('Cost Margin'!$I18="",'Cost Margin'!$B$9,'Cost Margin'!$I18),Z$6)<MAX(IF('Cost Margin'!$H18="",'Cost Margin'!$B$8,'Cost Margin'!$H18),Z$5),0,IFERROR(NETWORKDAYS(MAX(IF('Cost Margin'!$H18="",'Cost Margin'!$B$8,'Cost Margin'!$H18),Z$5),MIN(IF('Cost Margin'!$I18="",'Cost Margin'!$B$9,'Cost Margin'!$I18),Z$6),INDEX(Settings!$J$7:$M$60,0,MATCH('Cost Margin'!$C18,Settings!$J$6:$M$6,0))),NETWORKDAYS(MAX(IF('Cost Margin'!$H18="",'Cost Margin'!$B$8,'Cost Margin'!$H18),Z$5),MIN(IF('Cost Margin'!$I18="",'Cost Margin'!$B$9,'Cost Margin'!$I18),Z$6))))) -> 0
A11: 3 | B11: =IF('Cost Margin'!A19="","",'Cost Margin'!A19) | C11: =IF(OR(C$5="",'Cost Margin'!$A19="",IF('Cost Margin'!$H19="",'Cost Margin'!$B$8,'Cost Margin'!$H19)="",IF('Cost Margin'!$I19="",'Cost Margin'!$B$9,'Cost Margin'!$I19)=""),0,IF(MIN(IF('Cost Margin'!$I19="",'Cost Margin'!$B$9,'Cost Margin'!$I19),C$6)<MAX(IF('Cost Margin'!$H19="",'Cost Margin'!$B$8,'Cost Margin'!$H19),C$5),0,IFERROR(NETWORKDAYS(MAX(IF('Cost Margin'!$H19="",'Cost Margin'!$B$8,'Cost Margin'!$H19),C$5),MIN(IF('Cost Margin'!$I19="",'Cost Margin'!$B$9,'Cost Margin'!$I19),C$6),INDEX(Settings!$J$7:$M$60,0,MATCH('Cost Margin'!$C19,Settings!$J$6:$M$6,0))),NETWORKDAYS(MAX(IF('Cost Margin'!$H19="",'Cost Margin'!$B$8,'Cost Margin'!$H19),C$5),MIN(IF('Cost Margin'!$I19="",'Cost Margin'!$B$9,'Cost Margin'!$I19),C$6))))) -> 0 | D11: =IF(OR(D$5="",'Cost Margin'!$A19="",IF('Cost Margin'!$H19="",'Cost Margin'!$B$8,'Cost Margin'!$H19)="",IF('Cost Margin'!$I19="",'Cost Margin'!$B$9,'Cost Margin'!$I19)=""),0,IF(MIN(IF('Cost Margin'!$I19="",'Cost Margin'!$B$9,'Cost Margin'!$I19),D$6)<MAX(IF('Cost Margin'!$H19="",'Cost Margin'!$B$8,'Cost Margin'!$H19),D$5),0,IFERROR(NETWORKDAYS(MAX(IF('Cost Margin'!$H19="",'Cost Margin'!$B$8,'Cost Margin'!$H19),D$5),MIN(IF('Cost Margin'!$I19="",'Cost Margin'!$B$9,'Cost Margin'!$I19),D$6),INDEX(Settings!$J$7:$M$60,0,MATCH('Cost Margin'!$C19,Settings!$J$6:$M$6,0))),NETWORKDAYS(MAX(IF('Cost Margin'!$H19="",'Cost Margin'!$B$8,'Cost Margin'!$H19),D$5),MIN(IF('Cost Margin'!$I19="",'Cost Margin'!$B$9,'Cost Margin'!$I19),D$6))))) -> 0 | E11: =IF(OR(E$5="",'Cost Margin'!$A19="",IF('Cost Margin'!$H19="",'Cost Margin'!$B$8,'Cost Margin'!$H19)="",IF('Cost Margin'!$I19="",'Cost Margin'!$B$9,'Cost Margin'!$I19)=""),0,IF(MIN(IF('Cost Margin'!$I19="",'Cost Margin'!$B$9,'Cost Margin'!$I19),E$6)<MAX(IF('Cost Margin'!$H19="",'Cost Margin'!$B$8,'Cost Margin'!$H19),E$5),0,IFERROR(NETWORKDAYS(MAX(IF('Cost Margin'!$H19="",'Cost Margin'!$B$8,'Cost Margin'!$H19),E$5),MIN(IF('Cost Margin'!$I19="",'Cost Margin'!$B$9,'Cost Margin'!$I19),E$6),INDEX(Settings!$J$7:$M$60,0,MATCH('Cost Margin'!$C19,Settings!$J$6:$M$6,0))),NETWORKDAYS(MAX(IF('Cost Margin'!$H19="",'Cost Margin'!$B$8,'Cost Margin'!$H19),E$5),MIN(IF('Cost Margin'!$I19="",'Cost Margin'!$B$9,'Cost Margin'!$I19),E$6))))) -> 0 | F11: =IF(OR(F$5="",'Cost Margin'!$A19="",IF('Cost Margin'!$H19="",'Cost Margin'!$B$8,'Cost Margin'!$H19)="",IF('Cost Margin'!$I19="",'Cost Margin'!$B$9,'Cost Margin'!$I19)=""),0,IF(MIN(IF('Cost Margin'!$I19="",'Cost Margin'!$B$9,'Cost Margin'!$I19),F$6)<MAX(IF('Cost Margin'!$H19="",'Cost Margin'!$B$8,'Cost Margin'!$H19),F$5),0,IFERROR(NETWORKDAYS(MAX(IF('Cost Margin'!$H19="",'Cost Margin'!$B$8,'Cost Margin'!$H19),F$5),MIN(IF('Cost Margin'!$I19="",'Cost Margin'!$B$9,'Cost Margin'!$I19),F$6),INDEX(Settings!$J$7:$M$60,0,MATCH('Cost Margin'!$C19,Settings!$J$6:$M$6,0))),NETWORKDAYS(MAX(IF('Cost Margin'!$H19="",'Cost Margin'!$B$8,'Cost Margin'!$H19),F$5),MIN(IF('Cost Margin'!$I19="",'Cost Margin'!$B$9,'Cost Margin'!$I19),F$6))))) -> 0 | G11: =IF(OR(G$5="",'Cost Margin'!$A19="",IF('Cost Margin'!$H19="",'Cost Margin'!$B$8,'Cost Margin'!$H19)="",IF('Cost Margin'!$I19="",'Cost Margin'!$B$9,'Cost Margin'!$I19)=""),0,IF(MIN(IF('Cost Margin'!$I19="",'Cost Margin'!$B$9,'Cost Margin'!$I19),G$6)<MAX(IF('Cost Margin'!$H19="",'Cost Margin'!$B$8,'Cost Margin'!$H19),G$5),0,IFERROR(NETWORKDAYS(MAX(IF('Cost Margin'!$H19="",'Cost Margin'!$B$8,'Cost Margin'!$H19),G$5),MIN(IF('Cost Margin'!$I19="",'Cost Margin'!$B$9,'Cost Margin'!$I19),G$6),INDEX(Settings!$J$7:$M$60,0,MATCH('Cost Margin'!$C19,Settings!$J$6:$M$6,0))),NETWORKDAYS(MAX(IF('Cost Margin'!$H19="",'Cost Margin'!$B$8,'Cost Margin'!$H19),G$5),MIN(IF('Cost Margin'!$I19="",'Cost Margin'!$B$9,'Cost Margin'!$I19),G$6))))) -> 0 | H11: =IF(OR(H$5="",'Cost Margin'!$A19="",IF('Cost Margin'!$H19="",'Cost Margin'!$B$8,'Cost Margin'!$H19)="",IF('Cost Margin'!$I19="",'Cost Margin'!$B$9,'Cost Margin'!$I19)=""),0,IF(MIN(IF('Cost Margin'!$I19="",'Cost Margin'!$B$9,'Cost Margin'!$I19),H$6)<MAX(IF('Cost Margin'!$H19="",'Cost Margin'!$B$8,'Cost Margin'!$H19),H$5),0,IFERROR(NETWORKDAYS(MAX(IF('Cost Margin'!$H19="",'Cost Margin'!$B$8,'Cost Margin'!$H19),H$5),MIN(IF('Cost Margin'!$I19="",'Cost Margin'!$B$9,'Cost Margin'!$I19),H$6),INDEX(Settings!$J$7:$M$60,0,MATCH('Cost Margin'!$C19,Settings!$J$6:$M$6,0))),NETWORKDAYS(MAX(IF('Cost Margin'!$H19="",'Cost Margin'!$B$8,'Cost Margin'!$H19),H$5),MIN(IF('Cost Margin'!$I19="",'Cost Margin'!$B$9,'Cost Margin'!$I19),H$6))))) -> 0 | I11: =IF(OR(I$5="",'Cost Margin'!$A19="",IF('Cost Margin'!$H19="",'Cost Margin'!$B$8,'Cost Margin'!$H19)="",IF('Cost Margin'!$I19="",'Cost Margin'!$B$9,'Cost Margin'!$I19)=""),0,IF(MIN(IF('Cost Margin'!$I19="",'Cost Margin'!$B$9,'Cost Margin'!$I19),I$6)<MAX(IF('Cost Margin'!$H19="",'Cost Margin'!$B$8,'Cost Margin'!$H19),I$5),0,IFERROR(NETWORKDAYS(MAX(IF('Cost Margin'!$H19="",'Cost Margin'!$B$8,'Cost Margin'!$H19),I$5),MIN(IF('Cost Margin'!$I19="",'Cost Margin'!$B$9,'Cost Margin'!$I19),I$6),INDEX(Settings!$J$7:$M$60,0,MATCH('Cost Margin'!$C19,Settings!$J$6:$M$6,0))),NETWORKDAYS(MAX(IF('Cost Margin'!$H19="",'Cost Margin'!$B$8,'Cost Margin'!$H19),I$5),MIN(IF('Cost Margin'!$I19="",'Cost Margin'!$B$9,'Cost Margin'!$I19),I$6))))) -> 0 | J11: =IF(OR(J$5="",'Cost Margin'!$A19="",IF('Cost Margin'!$H19="",'Cost Margin'!$B$8,'Cost Margin'!$H19)="",IF('Cost Margin'!$I19="",'Cost Margin'!$B$9,'Cost Margin'!$I19)=""),0,IF(MIN(IF('Cost Margin'!$I19="",'Cost Margin'!$B$9,'Cost Margin'!$I19),J$6)<MAX(IF('Cost Margin'!$H19="",'Cost Margin'!$B$8,'Cost Margin'!$H19),J$5),0,IFERROR(NETWORKDAYS(MAX(IF('Cost Margin'!$H19="",'Cost Margin'!$B$8,'Cost Margin'!$H19),J$5),MIN(IF('Cost Margin'!$I19="",'Cost Margin'!$B$9,'Cost Margin'!$I19),J$6),INDEX(Settings!$J$7:$M$60,0,MATCH('Cost Margin'!$C19,Settings!$J$6:$M$6,0))),NETWORKDAYS(MAX(IF('Cost Margin'!$H19="",'Cost Margin'!$B$8,'Cost Margin'!$H19),J$5),MIN(IF('Cost Margin'!$I19="",'Cost Margin'!$B$9,'Cost Margin'!$I19),J$6))))) -> 0 | ... Z11: =IF(OR(Z$5="",'Cost Margin'!$A19="",IF('Cost Margin'!$H19="",'Cost Margin'!$B$8,'Cost Margin'!$H19)="",IF('Cost Margin'!$I19="",'Cost Margin'!$B$9,'Cost Margin'!$I19)=""),0,IF(MIN(IF('Cost Margin'!$I19="",'Cost Margin'!$B$9,'Cost Margin'!$I19),Z$6)<MAX(IF('Cost Margin'!$H19="",'Cost Margin'!$B$8,'Cost Margin'!$H19),Z$5),0,IFERROR(NETWORKDAYS(MAX(IF('Cost Margin'!$H19="",'Cost Margin'!$B$8,'Cost Margin'!$H19),Z$5),MIN(IF('Cost Margin'!$I19="",'Cost Margin'!$B$9,'Cost Margin'!$I19),Z$6),INDEX(Settings!$J$7:$M$60,0,MATCH('Cost Margin'!$C19,Settings!$J$6:$M$6,0))),NETWORKDAYS(MAX(IF('Cost Margin'!$H19="",'Cost Margin'!$B$8,'Cost Margin'!$H19),Z$5),MIN(IF('Cost Margin'!$I19="",'Cost Margin'!$B$9,'Cost Margin'!$I19),Z$6))))) -> 0
A12: 4 | B12: =IF('Cost Margin'!A20="","",'Cost Margin'!A20) | C12: =IF(OR(C$5="",'Cost Margin'!$A20="",IF('Cost Margin'!$H20="",'Cost Margin'!$B$8,'Cost Margin'!$H20)="",IF('Cost Margin'!$I20="",'Cost Margin'!$B$9,'Cost Margin'!$I20)=""),0,IF(MIN(IF('Cost Margin'!$I20="",'Cost Margin'!$B$9,'Cost Margin'!$I20),C$6)<MAX(IF('Cost Margin'!$H20="",'Cost Margin'!$B$8,'Cost Margin'!$H20),C$5),0,IFERROR(NETWORKDAYS(MAX(IF('Cost Margin'!$H20="",'Cost Margin'!$B$8,'Cost Margin'!$H20),C$5),MIN(IF('Cost Margin'!$I20="",'Cost Margin'!$B$9,'Cost Margin'!$I20),C$6),INDEX(Settings!$J$7:$M$60,0,MATCH('Cost Margin'!$C20,Settings!$J$6:$M$6,0))),NETWORKDAYS(MAX(IF('Cost Margin'!$H20="",'Cost Margin'!$B$8,'Cost Margin'!$H20),C$5),MIN(IF('Cost Margin'!$I20="",'Cost Margin'!$B$9,'Cost Margin'!$I20),C$6))))) -> 0 | D12: =IF(OR(D$5="",'Cost Margin'!$A20="",IF('Cost Margin'!$H20="",'Cost Margin'!$B$8,'Cost Margin'!$H20)="",IF('Cost Margin'!$I20="",'Cost Margin'!$B$9,'Cost Margin'!$I20)=""),0,IF(MIN(IF('Cost Margin'!$I20="",'Cost Margin'!$B$9,'Cost Margin'!$I20),D$6)<MAX(IF('Cost Margin'!$H20="",'Cost Margin'!$B$8,'Cost Margin'!$H20),D$5),0,IFERROR(NETWORKDAYS(MAX(IF('Cost Margin'!$H20="",'Cost Margin'!$B$8,'Cost Margin'!$H20),D$5),MIN(IF('Cost Margin'!$I20="",'Cost Margin'!$B$9,'Cost Margin'!$I20),D$6),INDEX(Settings!$J$7:$M$60,0,MATCH('Cost Margin'!$C20,Settings!$J$6:$M$6,0))),NETWORKDAYS(MAX(IF('Cost Margin'!$H20="",'Cost Margin'!$B$8,'Cost Margin'!$H20),D$5),MIN(IF('Cost Margin'!$I20="",'Cost Margin'!$B$9,'Cost Margin'!$I20),D$6))))) -> 0 | E12: =IF(OR(E$5="",'Cost Margin'!$A20="",IF('Cost Margin'!$H20="",'Cost Margin'!$B$8,'Cost Margin'!$H20)="",IF('Cost Margin'!$I20="",'Cost Margin'!$B$9,'Cost Margin'!$I20)=""),0,IF(MIN(IF('Cost Margin'!$I20="",'Cost Margin'!$B$9,'Cost Margin'!$I20),E$6)<MAX(IF('Cost Margin'!$H20="",'Cost Margin'!$B$8,'Cost Margin'!$H20),E$5),0,IFERROR(NETWORKDAYS(MAX(IF('Cost Margin'!$H20="",'Cost Margin'!$B$8,'Cost Margin'!$H20),E$5),MIN(IF('Cost Margin'!$I20="",'Cost Margin'!$B$9,'Cost Margin'!$I20),E$6),INDEX(Settings!$J$7:$M$60,0,MATCH('Cost Margin'!$C20,Settings!$J$6:$M$6,0))),NETWORKDAYS(MAX(IF('Cost Margin'!$H20="",'Cost Margin'!$B$8,'Cost Margin'!$H20),E$5),MIN(IF('Cost Margin'!$I20="",'Cost Margin'!$B$9,'Cost Margin'!$I20),E$6))))) -> 0 | F12: =IF(OR(F$5="",'Cost Margin'!$A20="",IF('Cost Margin'!$H20="",'Cost Margin'!$B$8,'Cost Margin'!$H20)="",IF('Cost Margin'!$I20="",'Cost Margin'!$B$9,'Cost Margin'!$I20)=""),0,IF(MIN(IF('Cost Margin'!$I20="",'Cost Margin'!$B$9,'Cost Margin'!$I20),F$6)<MAX(IF('Cost Margin'!$H20="",'Cost Margin'!$B$8,'Cost Margin'!$H20),F$5),0,IFERROR(NETWORKDAYS(MAX(IF('Cost Margin'!$H20="",'Cost Margin'!$B$8,'Cost Margin'!$H20),F$5),MIN(IF('Cost Margin'!$I20="",'Cost Margin'!$B$9,'Cost Margin'!$I20),F$6),INDEX(Settings!$J$7:$M$60,0,MATCH('Cost Margin'!$C20,Settings!$J$6:$M$6,0))),NETWORKDAYS(MAX(IF('Cost Margin'!$H20="",'Cost Margin'!$B$8,'Cost Margin'!$H20),F$5),MIN(IF('Cost Margin'!$I20="",'Cost Margin'!$B$9,'Cost Margin'!$I20),F$6))))) -> 0 | G12: =IF(OR(G$5="",'Cost Margin'!$A20="",IF('Cost Margin'!$H20="",'Cost Margin'!$B$8,'Cost Margin'!$H20)="",IF('Cost Margin'!$I20="",'Cost Margin'!$B$9,'Cost Margin'!$I20)=""),0,IF(MIN(IF('Cost Margin'!$I20="",'Cost Margin'!$B$9,'Cost Margin'!$I20),G$6)<MAX(IF('Cost Margin'!$H20="",'Cost Margin'!$B$8,'Cost Margin'!$H20),G$5),0,IFERROR(NETWORKDAYS(MAX(IF('Cost Margin'!$H20="",'Cost Margin'!$B$8,'Cost Margin'!$H20),G$5),MIN(IF('Cost Margin'!$I20="",'Cost Margin'!$B$9,'Cost Margin'!$I20),G$6),INDEX(Settings!$J$7:$M$60,0,MATCH('Cost Margin'!$C20,Settings!$J$6:$M$6,0))),NETWORKDAYS(MAX(IF('Cost Margin'!$H20="",'Cost Margin'!$B$8,'Cost Margin'!$H20),G$5),MIN(IF('Cost Margin'!$I20="",'Cost Margin'!$B$9,'Cost Margin'!$I20),G$6))))) -> 0 | H12: =IF(OR(H$5="",'Cost Margin'!$A20="",IF('Cost Margin'!$H20="",'Cost Margin'!$B$8,'Cost Margin'!$H20)="",IF('Cost Margin'!$I20="",'Cost Margin'!$B$9,'Cost Margin'!$I20)=""),0,IF(MIN(IF('Cost Margin'!$I20="",'Cost Margin'!$B$9,'Cost Margin'!$I20),H$6)<MAX(IF('Cost Margin'!$H20="",'Cost Margin'!$B$8,'Cost Margin'!$H20),H$5),0,IFERROR(NETWORKDAYS(MAX(IF('Cost Margin'!$H20="",'Cost Margin'!$B$8,'Cost Margin'!$H20),H$5),MIN(IF('Cost Margin'!$I20="",'Cost Margin'!$B$9,'Cost Margin'!$I20),H$6),INDEX(Settings!$J$7:$M$60,0,MATCH('Cost Margin'!$C20,Settings!$J$6:$M$6,0))),NETWORKDAYS(MAX(IF('Cost Margin'!$H20="",'Cost Margin'!$B$8,'Cost Margin'!$H20),H$5),MIN(IF('Cost Margin'!$I20="",'Cost Margin'!$B$9,'Cost Margin'!$I20),H$6))))) -> 0 | I12: =IF(OR(I$5="",'Cost Margin'!$A20="",IF('Cost Margin'!$H20="",'Cost Margin'!$B$8,'Cost Margin'!$H20)="",IF('Cost Margin'!$I20="",'Cost Margin'!$B$9,'Cost Margin'!$I20)=""),0,IF(MIN(IF('Cost Margin'!$I20="",'Cost Margin'!$B$9,'Cost Margin'!$I20),I$6)<MAX(IF('Cost Margin'!$H20="",'Cost Margin'!$B$8,'Cost Margin'!$H20),I$5),0,IFERROR(NETWORKDAYS(MAX(IF('Cost Margin'!$H20="",'Cost Margin'!$B$8,'Cost Margin'!$H20),I$5),MIN(IF('Cost Margin'!$I20="",'Cost Margin'!$B$9,'Cost Margin'!$I20),I$6),INDEX(Settings!$J$7:$M$60,0,MATCH('Cost Margin'!$C20,Settings!$J$6:$M$6,0))),NETWORKDAYS(MAX(IF('Cost Margin'!$H20="",'Cost Margin'!$B$8,'Cost Margin'!$H20),I$5),MIN(IF('Cost Margin'!$I20="",'Cost Margin'!$B$9,'Cost Margin'!$I20),I$6))))) -> 0 | J12: =IF(OR(J$5="",'Cost Margin'!$A20="",IF('Cost Margin'!$H20="",'Cost Margin'!$B$8,'Cost Margin'!$H20)="",IF('Cost Margin'!$I20="",'Cost Margin'!$B$9,'Cost Margin'!$I20)=""),0,IF(MIN(IF('Cost Margin'!$I20="",'Cost Margin'!$B$9,'Cost Margin'!$I20),J$6)<MAX(IF('Cost Margin'!$H20="",'Cost Margin'!$B$8,'Cost Margin'!$H20),J$5),0,IFERROR(NETWORKDAYS(MAX(IF('Cost Margin'!$H20="",'Cost Margin'!$B$8,'Cost Margin'!$H20),J$5),MIN(IF('Cost Margin'!$I20="",'Cost Margin'!$B$9,'Cost Margin'!$I20),J$6),INDEX(Settings!$J$7:$M$60,0,MATCH('Cost Margin'!$C20,Settings!$J$6:$M$6,0))),NETWORKDAYS(MAX(IF('Cost Margin'!$H20="",'Cost Margin'!$B$8,'Cost Margin'!$H20),J$5),MIN(IF('Cost Margin'!$I20="",'Cost Margin'!$B$9,'Cost Margin'!$I20),J$6))))) -> 0 | ... Z12: =IF(OR(Z$5="",'Cost Margin'!$A20="",IF('Cost Margin'!$H20="",'Cost Margin'!$B$8,'Cost Margin'!$H20)="",IF('Cost Margin'!$I20="",'Cost Margin'!$B$9,'Cost Margin'!$I20)=""),0,IF(MIN(IF('Cost Margin'!$I20="",'Cost Margin'!$B$9,'Cost Margin'!$I20),Z$6)<MAX(IF('Cost Margin'!$H20="",'Cost Margin'!$B$8,'Cost Margin'!$H20),Z$5),0,IFERROR(NETWORKDAYS(MAX(IF('Cost Margin'!$H20="",'Cost Margin'!$B$8,'Cost Margin'!$H20),Z$5),MIN(IF('Cost Margin'!$I20="",'Cost Margin'!$B$9,'Cost Margin'!$I20),Z$6),INDEX(Settings!$J$7:$M$60,0,MATCH('Cost Margin'!$C20,Settings!$J$6:$M$6,0))),NETWORKDAYS(MAX(IF('Cost Margin'!$H20="",'Cost Margin'!$B$8,'Cost Margin'!$H20),Z$5),MIN(IF('Cost Margin'!$I20="",'Cost Margin'!$B$9,'Cost Margin'!$I20),Z$6))))) -> 0
