Workbook

Sheet Cost Margin
A1: Cost margin sheet
A2: Yellow = inputs (blue text). Grey = calculated. * = required. Pick the engagement type first — it decides how revenue is counted and which fields apply.
V3: Project summary
A4: Engagement type * (pick first) | C4: Fixed cost / Assessment → Total project price. MSP → Monthly fee. Time & materials / Staff augmentation → each row's bill rate. Fields not needed for the chosen type turn grey. | V4: Engagement type | W4: =IF(B4="","",B4)
A5: Project / engagement name | V5: Duration (months) | W5: =B10
A6: Client | V6: Project revenue | W6: =IF(B4="","",IF(B4="MSP",IF(OR(B12="",B10=""),"",B12*B10),IF(OR(B4="Time & materials",B4="Staff augmentation"),O37,IF(B11="","",B11))))
A7: Currency | B7: USD | V7: Pass-through expenses billed to client | W7: =H53 -> 0
A8: Project start * | C8: For Staff augmentation these are the forecast window; each resource's own dates default to them and can be changed. | V8: Total revenue | W8: =IF(W6="","",W6+W7)
A9: Project end * | V9: Labour cost | W9: =P37 -> 0
A10: Duration (months, partial months by days) | B10: =IF(OR(B8="",B9=""),"",SUM(Monthly!$C$4:$Z$4)) | C10: =IF(OR(B8="",B9=""),"",IF(B9<B8,"End is before start",DATEDIF(B8,B9+1,"M")&" month(s) "&DATEDIF(B8,B9+1,"MD")&" day(s) — "&(B9-B8+1)&" calendar days inclusive")) | V10: Burden cost | W10: =Q37 -> 0
A11: Total project price * (Fixed cost / Assessment) | C11: =IF(OR(B4="Fixed cost",B4="Assessment"),IF(B11="","← required for this engagement type",""),IF(B11="","","Not used for this engagement type")) | V11: Additional costs | W11: =G53 -> 0
A12: Monthly fee * (MSP) | C12: =IF(B4="MSP",IF(B12="","← required for MSP",""),IF(B12="","","Not used for this engagement type")) | V12: Total cost | W12: =W9+W10+W11 -> 0
A13: Additional costs on this project? * (Y/N) | C13: =IF(B13="","← required: Y if there are travel, licences, subcontractor or other costs; N if none","") -> ← required: Y if there are travel, licences, subcontractor or other costs; N if none | V13: Gross margin $ | W13: =IF(W8="","",W8-W12)
A14: Same start/end for every resource? * (Y/N) | C14: =IF(B14="","← required: Y = everyone works the full project window (row dates are ignored); N = set each person's own Start/End below","") -> ← required: Y = everyone works the full project window (row dates are ignored); N = set each person's own Start/End below | V14: Gross margin % | W14: =IF(OR(W8="",W8=0),"",W13/W8)
A15: Staffing — one row per person. To remove a person, clear that row's yellow cells; a row with no Role is ignored. Don't delete rows — the Monthly tab maps to them. | V15: Project GM floor % | W15: =Settings!$B$6 -> 0.35
A16: Role * | B16: Seniority * | C16: Location * | D16: Employment type * (W-2 or 1099 — sets the burden %) | E16: Assignment / project (optional — group resources; Staff augmentation) | F16: Utilization % | G16: Hours (auto — use Hours override to change) | H16: Bill rate (what we CHARGE the client per hour — T&M / Staff aug only) | I16: Our cost / hour * (what the person COSTS us, before burden — pre-filled from the Settings rate card; overwrite if known) | J16: Start (B14 = Y: project start for everyone, greyed. B14 = N: pre-filled, change if the person joins later) | K16: End (B14 = Y: project end for everyone. B14 = N: pre-filled, change if they leave earlier) | L16: Working days | M16: Hours override (optional) | N16: Burden % | O16: Labour at bill rate (revenue, T&M / Staff aug) | P16: Labour cost (hours × cost/hr) | Q16: Burden cost | R16: Loaded cost (labour + burden) | S16: GM floor % | T16: Row GM % (T&M / Staff aug) | V16: Status | W16: =IF(W18<>"","INCOMPLETE — see below",IF(OR(W14="",W15=""),"",IF(W14>=W15,"PASS — GM "&TEXT(W14,"0.0%")&" ≥ floor "&TEXT(W15,"0.0%"),"BELOW FLOOR — GM "&TEXT(W14,"0.0%")&" < floor "&TEXT(W15,"0.0%")))) -> INCOMPLETE — see below
G17: =IF(M17<>"",M17,IF(L17="","",L17*Settings!$B$5*IF(F17="",1,F17))) | I17: =IF(OR(B17="",C17="",D17=""),"",IFERROR(INDEX(Settings!$B$17:$I$20,MATCH(B17,Settings!$A$17:$A$20,0),(MATCH(C17,Settings!$A$9:$A$12,0)-1)*2+IF(D17="W-2 / Employee",1,2)),"")) | J17: =IF(OR(A17="",$B$8=""),"",$B$8) | K17: =IF(OR(A17="",$B$9=""),"",$B$9) | L17: =IF(OR(A17="",IF(OR($B$14="Y",J17=""),$B$8,J17)="",IF(OR($B$14="Y",K17=""),$B$9,K17)=""),"",IFERROR(NETWORKDAYS(IF(OR($B$14="Y",J17=""),$B$8,J17),IF(OR($B$14="Y",K17=""),$B$9,K17),INDEX(Settings!$A$35:$D$74,0,MATCH(C17,Settings!$A$34:$D$34,0))),NETWORKDAYS(IF(OR($B$14="Y",J17=""),$B$8,J17),IF(OR($B$14="Y",K17=""),$B$9,K17)))) | N17: =IF(OR(C17="",D17=""),0,IFERROR(INDEX(Settings!$B$9:$C$12,MATCH(C17,Settings!$A$9:$A$12,0),IF(D17="W-2 / Employee",1,2)),0)) -> 0 | O17: =IF(OR(G17="",H17=""),0,G17*H17) -> 0 | P17: =IF(OR(G17="",I17=""),0,G17*I17) -> 0 | Q17: =P17*N17 -> 0 | R17: =P17+Q17 -> 0 | S17: =IF(C17="",0,IFERROR(INDEX(Settings!$D$9:$D$12,MATCH(C17,Settings!$A$9:$A$12,0)),0)) -> 0 | T17: =IF(O17=0,"",(O17-R17)/O17)
G18: =IF(M18<>"",M18,IF(L18="","",L18*Settings!$B$5*IF(F18="",1,F18))) | I18: =IF(OR(B18="",C18="",D18=""),"",IFERROR(INDEX(Settings!$B$17:$I$20,MATCH(B18,Settings!$A$17:$A$20,0),(MATCH(C18,Settings!$A$9:$A$12,0)-1)*2+IF(D18="W-2 / Employee",1,2)),"")) | J18: =IF(OR(A18="",$B$8=""),"",$B$8) | K18: =IF(OR(A18="",$B$9=""),"",$B$9) | L18: =IF(OR(A18="",IF(OR($B$14="Y",J18=""),$B$8,J18)="",IF(OR($B$14="Y",K18=""),$B$9,K18)=""),"",IFERROR(NETWORKDAYS(IF(OR($B$14="Y",J18=""),$B$8,J18),IF(OR($B$14="Y",K18=""),$B$9,K18),INDEX(Settings!$A$35:$D$74,0,MATCH(C18,Settings!$A$34:$D$34,0))),NETWORKDAYS(IF(OR($B$14="Y",J18=""),$B$8,J18),IF(OR($B$14="Y",K18=""),$B$9,K18)))) | N18: =IF(OR(C18="",D18=""),0,IFERROR(INDEX(Settings!$B$9:$C$12,MATCH(C18,Settings!$A$9:$A$12,0),IF(D18="W-2 / Employee",1,2)),0)) -> 0 | O18: =IF(OR(G18="",H18=""),0,G18*H18) -> 0 | P18: =IF(OR(G18="",I18=""),0,G18*I18) -> 0 | Q18: =P18*N18 -> 0 | R18: =P18+Q18 -> 0 | S18: =IF(C18="",0,IFERROR(INDEX(Settings!$D$9:$D$12,MATCH(C18,Settings!$A$9:$A$12,0)),0)) -> 0 | T18: =IF(O18=0,"",(O18-R18)/O18) | V18: Missing inputs | W18: =TRIM(IF(B4="","Engagement type. ","")&IF(OR(B8="",B9=""),"Project dates. ","")&IF(AND(OR(B4="Fixed cost",B4="Assessment"),B11=""),"Total project price. ","")&IF(AND(B4="MSP",B12=""),"Monthly fee. ","")&IF(B13="","Additional costs Y/N. ","")&IF(B14="","Same start/end for every resource Y/N. ","")&IF(COUNTIF(I41:I52,"Pick*")>0,"Billed to client Y/N (column F) on additional cost rows. ","")&IF(COUNTIFS(A17:A36,"<>",D17:D36,"")>0,"Employment type (column D) on staffing rows. ","")&IF(COUNTIFS(A17:A36,"<>",I17:I36,"")>0,"Our cost/hour (column I) on staffing rows — pick Seniority + Location or type it. ","")&IF(AND(OR(B4="Time & materials",B4="Staff augmentation"),COUNTIFS(A17:A36,"<>",H17:H36,"")>0),"Bill rate (column H) on staffing rows. ","")) -> Engagement type. Project dates. Additional costs Y/N. Same start/end for every resource Y/N.
G19: =IF(M19<>"",M19,IF(L19="","",L19*Settings!$B$5*IF(F19="",1,F19))) | I19: =IF(OR(B19="",C19="",D19=""),"",IFERROR(INDEX(Settings!$B$17:$I$20,MATCH(B19,Settings!$A$17:$A$20,0),(MATCH(C19,Settings!$A$9:$A$12,0)-1)*2+IF(D19="W-2 / Employee",1,2)),"")) | J19: =IF(OR(A19="",$B$8=""),"",$B$8) | K19: =IF(OR(A19="",$B$9=""),"",$B$9) | L19: =IF(OR(A19="",IF(OR($B$14="Y",J19=""),$B$8,J19)="",IF(OR($B$14="Y",K19=""),$B$9,K19)=""),"",IFERROR(NETWORKDAYS(IF(OR($B$14="Y",J19=""),$B$8,J19),IF(OR($B$14="Y",K19=""),$B$9,K19),INDEX(Settings!$A$35:$D$74,0,MATCH(C19,Settings!$A$34:$D$34,0))),NETWORKDAYS(IF(OR($B$14="Y",J19=""),$B$8,J19),IF(OR($B$14="Y",K19=""),$B$9,K19)))) | N19: =IF(OR(C19="",D19=""),0,IFERROR(INDEX(Settings!$B$9:$C$12,MATCH(C19,Settings!$A$9:$A$12,0),IF(D19="W-2 / Employee",1,2)),0)) -> 0 | O19: =IF(OR(G19="",H19=""),0,G19*H19) -> 0 | P19: =IF(OR(G19="",I19=""),0,G19*I19) -> 0 | Q19: =P19*N19 -> 0 | R19: =P19+Q19 -> 0 | S19: =IF(C19="",0,IFERROR(INDEX(Settings!$D$9:$D$12,MATCH(C19,Settings!$A$9:$A$12,0)),0)) -> 0 | T19: =IF(O19=0,"",(O19-R19)/O19)
G20: =IF(M20<>"",M20,IF(L20="","",L20*Settings!$B$5*IF(F20="",1,F20))) | I20: =IF(OR(B20="",C20="",D20=""),"",IFERROR(INDEX(Settings!$B$17:$I$20,MATCH(B20,Settings!$A$17:$A$20,0),(MATCH(C20,Settings!$A$9:$A$12,0)-1)*2+IF(D20="W-2 / Employee",1,2)),"")) | J20: =IF(OR(A20="",$B$8=""),"",$B$8) | K20: =IF(OR(A20="",$B$9=""),"",$B$9) | L20: =IF(OR(A20="",IF(OR($B$14="Y",J20=""),$B$8,J20)="",IF(OR($B$14="Y",K20=""),$B$9,K20)=""),"",IFERROR(NETWORKDAYS(IF(OR($B$14="Y",J20=""),$B$8,J20),IF(OR($B$14="Y",K20=""),$B$9,K20),INDEX(Settings!$A$35:$D$74,0,MATCH(C20,Settings!$A$34:$D$34,0))),NETWORKDAYS(IF(OR($B$14="Y",J20=""),$B$8,J20),IF(OR($B$14="Y",K20=""),$B$9,K20)))) | N20: =IF(OR(C20="",D20=""),0,IFERROR(INDEX(Settings!$B$9:$C$12,MATCH(C20,Settings!$A$9:$A$12,0),IF(D20="W-2 / Employee",1,2)),0)) -> 0 | O20: =IF(OR(G20="",H20=""),0,G20*H20) -> 0 | P20: =IF(OR(G20="",I20=""),0,G20*I20) -> 0 | Q20: =P20*N20 -> 0 | R20: =P20+Q20 -> 0 | S20: =IF(C20="",0,IFERROR(INDEX(Settings!$D$9:$D$12,MATCH(C20,Settings!$A$9:$A$12,0)),0)) -> 0 | T20: =IF(O20=0,"",(O20-R20)/O20) | V20: Monthly view | W20: =IF(B10="","",IF(B10>2,"Required — see Monthly tab","Not needed (≤ 2 months)"))
G21: =IF(M21<>"",M21,IF(L21="","",L21*Settings!$B$5*IF(F21="",1,F21))) | I21: =IF(OR(B21="",C21="",D21=""),"",IFERROR(INDEX(Settings!$B$17:$I$20,MATCH(B21,Settings!$A$17:$A$20,0),(MATCH(C21,Settings!$A$9:$A$12,0)-1)*2+IF(D21="W-2 / Employee",1,2)),"")) | J21: =IF(OR(A21="",$B$8=""),"",$B$8) | K21: =IF(OR(A21="",$B$9=""),"",$B$9) | L21: =IF(OR(A21="",IF(OR($B$14="Y",J21=""),$B$8,J21)="",IF(OR($B$14="Y",K21=""),$B$9,K21)=""),"",IFERROR(NETWORKDAYS(IF(OR($B$14="Y",J21=""),$B$8,J21),IF(OR($B$14="Y",K21=""),$B$9,K21),INDEX(Settings!$A$35:$D$74,0,MATCH(C21,Settings!$A$34:$D$34,0))),NETWORKDAYS(IF(OR($B$14="Y",J21=""),$B$8,J21),IF(OR($B$14="Y",K21=""),$B$9,K21)))) | N21: =IF(OR(C21="",D21=""),0,IFERROR(INDEX(Settings!$B$9:$C$12,MATCH(C21,Settings!$A$9:$A$12,0),IF(D21="W-2 / Employee",1,2)),0)) -> 0 | O21: =IF(OR(G21="",H21=""),0,G21*H21) -> 0 | P21: =IF(OR(G21="",I21=""),0,G21*I21) -> 0 | Q21: =P21*N21 -> 0 | R21: =P21+Q21 -> 0 | S21: =IF(C21="",0,IFERROR(INDEX(Settings!$D$9:$D$12,MATCH(C21,Settings!$A$9:$A$12,0)),0)) -> 0 | T21: =IF(O21=0,"",(O21-R21)/O21)
G22: =IF(M22<>"",M22,IF(L22="","",L22*Settings!$B$5*IF(F22="",1,F22))) | I22: =IF(OR(B22="",C22="",D22=""),"",IFERROR(INDEX(Settings!$B$17:$I$20,MATCH(B22,Settings!$A$17:$A$20,0),(MATCH(C22,Settings!$A$9:$A$12,0)-1)*2+IF(D22="W-2 / Employee",1,2)),"")) | J22: =IF(OR(A22="",$B$8=""),"",$B$8) | K22: =IF(OR(A22="",$B$9=""),"",$B$9) | L22: =IF(OR(A22="",IF(OR($B$14="Y",J22=""),$B$8,J22)="",IF(OR($B$14="Y",K22=""),$B$9,K22)=""),"",IFERROR(NETWORKDAYS(IF(OR($B$14="Y",J22=""),$B$8,J22),IF(OR($B$14="Y",K22=""),$B$9,K22),INDEX(Settings!$A$35:$D$74,0,MATCH(C22,Settings!$A$34:$D$34,0))),NETWORKDAYS(IF(OR($B$14="Y",J22=""),$B$8,J22),IF(OR($B$14="Y",K22=""),$B$9,K22)))) | N22: =IF(OR(C22="",D22=""),0,IFERROR(INDEX(Settings!$B$9:$C$12,MATCH(C22,Settings!$A$9:$A$12,0),IF(D22="W-2 / Employee",1,2)),0)) -> 0 | O22: =IF(OR(G22="",H22=""),0,G22*H22) -> 0 | P22: =IF(OR(G22="",I22=""),0,G22*I22) -> 0 | Q22: =P22*N22 -> 0 | R22: =P22+Q22 -> 0 | S22: =IF(C22="",0,IFERROR(INDEX(Settings!$D$9:$D$12,MATCH(C22,Settings!$A$9:$A$12,0)),0)) -> 0 | T22: =IF(O22=0,"",(O22-R22)/O22) | V22: Location check — each location's resources against their own floor (hourly types; fixed-price work is judged on the project floor only)
G23: =IF(M23<>"",M23,IF(L23="","",L23*Settings!$B$5*IF(F23="",1,F23))) | I23: =IF(OR(B23="",C23="",D23=""),"",IFERROR(INDEX(Settings!$B$17:$I$20,MATCH(B23,Settings!$A$17:$A$20,0),(MATCH(C23,Settings!$A$9:$A$12,0)-1)*2+IF(D23="W-2 / Employee",1,2)),"")) | J23: =IF(OR(A23="",$B$8=""),"",$B$8) | K23: =IF(OR(A23="",$B$9=""),"",$B$9) | L23: =IF(OR(A23="",IF(OR($B$14="Y",J23=""),$B$8,J23)="",IF(OR($B$14="Y",K23=""),$B$9,K23)=""),"",IFERROR(NETWORKDAYS(IF(OR($B$14="Y",J23=""),$B$8,J23),IF(OR($B$14="Y",K23=""),$B$9,K23),INDEX(Settings!$A$35:$D$74,0,MATCH(C23,Settings!$A$34:$D$34,0))),NETWORKDAYS(IF(OR($B$14="Y",J23=""),$B$8,J23),IF(OR($B$14="Y",K23=""),$B$9,K23)))) | N23: =IF(OR(C23="",D23=""),0,IFERROR(INDEX(Settings!$B$9:$C$12,MATCH(C23,Settings!$A$9:$A$12,0),IF(D23="W-2 / Employee",1,2)),0)) -> 0 | O23: =IF(OR(G23="",H23=""),0,G23*H23) -> 0 | P23: =IF(OR(G23="",I23=""),0,G23*I23) -> 0 | Q23: =P23*N23 -> 0 | R23: =P23+Q23 -> 0 | S23: =IF(C23="",0,IFERROR(INDEX(Settings!$D$9:$D$12,MATCH(C23,Settings!$A$9:$A$12,0)),0)) -> 0 | T23: =IF(O23=0,"",(O23-R23)/O23) | V23: Location | W23: Labour cost | X23: Share of labour | Y23: Resource floor | Z23: Revenue (hourly types) | AA23: GM % (hourly types) | AB23: Check
G24: =IF(M24<>"",M24,IF(L24="","",L24*Settings!$B$5*IF(F24="",1,F24))) | I24: =IF(OR(B24="",C24="",D24=""),"",IFERROR(INDEX(Settings!$B$17:$I$20,MATCH(B24,Settings!$A$17:$A$20,0),(MATCH(C24,Settings!$A$9:$A$12,0)-1)*2+IF(D24="W-2 / Employee",1,2)),"")) | J24: =IF(OR(A24="",$B$8=""),"",$B$8) | K24: =IF(OR(A24="",$B$9=""),"",$B$9) | L24: =IF(OR(A24="",IF(OR($B$14="Y",J24=""),$B$8,J24)="",IF(OR($B$14="Y",K24=""),$B$9,K24)=""),"",IFERROR(NETWORKDAYS(IF(OR($B$14="Y",J24=""),$B$8,J24),IF(OR($B$14="Y",K24=""),$B$9,K24),INDEX(Settings!$A$35:$D$74,0,MATCH(C24,Settings!$A$34:$D$34,0))),NETWORKDAYS(IF(OR($B$14="Y",J24=""),$B$8,J24),IF(OR($B$14="Y",K24=""),$B$9,K24)))) | N24: =IF(OR(C24="",D24=""),0,IFERROR(INDEX(Settings!$B$9:$C$12,MATCH(C24,Settings!$A$9:$A$12,0),IF(D24="W-2 / Employee",1,2)),0)) -> 0 | O24: =IF(OR(G24="",H24=""),0,G24*H24) -> 0 | P24: =IF(OR(G24="",I24=""),0,G24*I24) -> 0 | Q24: =P24*N24 -> 0 | R24: =P24+Q24 -> 0 | S24: =IF(C24="",0,IFERROR(INDEX(Settings!$D$9:$D$12,MATCH(C24,Settings!$A$9:$A$12,0)),0)) -> 0 | T24: =IF(O24=0,"",(O24-R24)/O24) | V24: =IF(Settings!A9="","",Settings!A9) -> US | W24: =IF(V24="","",SUMIF($C$17:$C$36,V24,$P$17:$P$36)) -> 0 | X24: =IF(OR(V24="",$P$37=0),"",W24/$P$37) | Y24: =IF(V24="","",Settings!D9) -> 0.35 | Z24: =IF(OR(V24="",NOT(OR($B$4="Time & materials",$B$4="Staff augmentation"))),"",SUMIF($C$17:$C$36,V24,$O$17:$O$36)) | AA24: =IF(OR(Z24="",Z24=0),"",(Z24-SUMIF($C$17:$C$36,V24,$R$17:$R$36))/Z24) | AB24: =IF(AA24="","",IF(AA24>=Y24,"OK","Under floor — review rates"))
G25: =IF(M25<>"",M25,IF(L25="","",L25*Settings!$B$5*IF(F25="",1,F25))) | I25: =IF(OR(B25="",C25="",D25=""),"",IFERROR(INDEX(Settings!$B$17:$I$20,MATCH(B25,Settings!$A$17:$A$20,0),(MATCH(C25,Settings!$A$9:$A$12,0)-1)*2+IF(D25="W-2 / Employee",1,2)),"")) | J25: =IF(OR(A25="",$B$8=""),"",$B$8) | K25: =IF(OR(A25="",$B$9=""),"",$B$9) | L25: =IF(OR(A25="",IF(OR($B$14="Y",J25=""),$B$8,J25)="",IF(OR($B$14="Y",K25=""),$B$9,K25)=""),"",IFERROR(NETWORKDAYS(IF(OR($B$14="Y",J25=""),$B$8,J25),IF(OR($B$14="Y",K25=""),$B$9,K25),INDEX(Settings!$A$35:$D$74,0,MATCH(C25,Settings!$A$34:$D$34,0))),NETWORKDAYS(IF(OR($B$14="Y",J25=""),$B$8,J25),IF(OR($B$14="Y",K25=""),$B$9,K25)))) | N25: =IF(OR(C25="",D25=""),0,IFERROR(INDEX(Settings!$B$9:$C$12,MATCH(C25,Settings!$A$9:$A$12,0),IF(D25="W-2 / Employee",1,2)),0)) -> 0 | O25: =IF(OR(G25="",H25=""),0,G25*H25) -> 0 | P25: =IF(OR(G25="",I25=""),0,G25*I25) -> 0 | Q25: =P25*N25 -> 0 | R25: =P25+Q25 -> 0 | S25: =IF(C25="",0,IFERROR(INDEX(Settings!$D$9:$D$12,MATCH(C25,Settings!$A$9:$A$12,0)),0)) -> 0 | T25: =IF(O25=0,"",(O25-R25)/O25) | V25: =IF(Settings!A10="","",Settings!A10) -> India | W25: =IF(V25="","",SUMIF($C$17:$C$36,V25,$P$17:$P$36)) -> 0 | X25: =IF(OR(V25="",$P$37=0),"",W25/$P$37) | Y25: =IF(V25="","",Settings!D10) -> 0.5 | Z25: =IF(OR(V25="",NOT(OR($B$4="Time & materials",$B$4="Staff augmentation"))),"",SUMIF($C$17:$C$36,V25,$O$17:$O$36)) | AA25: =IF(OR(Z25="",Z25=0),"",(Z25-SUMIF($C$17:$C$36,V25,$R$17:$R$36))/Z25) | AB25: =IF(AA25="","",IF(AA25>=Y25,"OK","Under floor — review rates"))
G26: =IF(M26<>"",M26,IF(L26="","",L26*Settings!$B$5*IF(F26="",1,F26))) | I26: =IF(OR(B26="",C26="",D26=""),"",IFERROR(INDEX(Settings!$B$17:$I$20,MATCH(B26,Settings!$A$17:$A$20,0),(MATCH(C26,Settings!$A$9:$A$12,0)-1)*2+IF(D26="W-2 / Employee",1,2)),"")) | J26: =IF(OR(A26="",$B$8=""),"",$B$8) | K26: =IF(OR(A26="",$B$9=""),"",$B$9) | L26: =IF(OR(A26="",IF(OR($B$14="Y",J26=""),$B$8,J26)="",IF(OR($B$14="Y",K26=""),$B$9,K26)=""),"",IFERROR(NETWORKDAYS(IF(OR($B$14="Y",J26=""),$B$8,J26),IF(OR($B$14="Y",K26=""),$B$9,K26),INDEX(Settings!$A$35:$D$74,0,MATCH(C26,Settings!$A$34:$D$34,0))),NETWORKDAYS(IF(OR($B$14="Y",J26=""),$B$8,J26),IF(OR($B$14="Y",K26=""),$B$9,K26)))) | N26: =IF(OR(C26="",D26=""),0,IFERROR(INDEX(Settings!$B$9:$C$12,MATCH(C26,Settings!$A$9:$A$12,0),IF(D26="W-2 / Employee",1,2)),0)) -> 0 | O26: =IF(OR(G26="",H26=""),0,G26*H26) -> 0 | P26: =IF(OR(G26="",I26=""),0,G26*I26) -> 0 | Q26: =P26*N26 -> 0 | R26: =P26+Q26 -> 0 | S26: =IF(C26="",0,IFERROR(INDEX(Settings!$D$9:$D$12,MATCH(C26,Settings!$A$9:$A$12,0)),0)) -> 0 | T26: =IF(O26=0,"",(O26-R26)/O26) | V26: =IF(Settings!A11="","",Settings!A11) | W26: =IF(V26="","",SUMIF($C$17:$C$36,V26,$P$17:$P$36)) | X26: =IF(OR(V26="",$P$37=0),"",W26/$P$37) | Y26: =IF(V26="","",Settings!D11) | Z26: =IF(OR(V26="",NOT(OR($B$4="Time & materials",$B$4="Staff augmentation"))),"",SUMIF($C$17:$C$36,V26,$O$17:$O$36)) | AA26: =IF(OR(Z26="",Z26=0),"",(Z26-SUMIF($C$17:$C$36,V26,$R$17:$R$36))/Z26) | AB26: =IF(AA26="","",IF(AA26>=Y26,"OK","Under floor — review rates"))
G27: =IF(M27<>"",M27,IF(L27="","",L27*Settings!$B$5*IF(F27="",1,F27))) | I27: =IF(OR(B27="",C27="",D27=""),"",IFERROR(INDEX(Settings!$B$17:$I$20,MATCH(B27,Settings!$A$17:$A$20,0),(MATCH(C27,Settings!$A$9:$A$12,0)-1)*2+IF(D27="W-2 / Employee",1,2)),"")) | J27: =IF(OR(A27="",$B$8=""),"",$B$8) | K27: =IF(OR(A27="",$B$9=""),"",$B$9) | L27: =IF(OR(A27="",IF(OR($B$14="Y",J27=""),$B$8,J27)="",IF(OR($B$14="Y",K27=""),$B$9,K27)=""),"",IFERROR(NETWORKDAYS(IF(OR($B$14="Y",J27=""),$B$8,J27),IF(OR($B$14="Y",K27=""),$B$9,K27),INDEX(Settings!$A$35:$D$74,0,MATCH(C27,Settings!$A$34:$D$34,0))),NETWORKDAYS(IF(OR($B$14="Y",J27=""),$B$8,J27),IF(OR($B$14="Y",K27=""),$B$9,K27)))) | N27: =IF(OR(C27="",D27=""),0,IFERROR(INDEX(Settings!$B$9:$C$12,MATCH(C27,Settings!$A$9:$A$12,0),IF(D27="W-2 / Employee",1,2)),0)) -> 0 | O27: =IF(OR(G27="",H27=""),0,G27*H27) -> 0 | P27: =IF(OR(G27="",I27=""),0,G27*I27) -> 0 | Q27: =P27*N27 -> 0 | R27: =P27+Q27 -> 0 | S27: =IF(C27="",0,IFERROR(INDEX(Settings!$D$9:$D$12,MATCH(C27,Settings!$A$9:$A$12,0)),0)) -> 0 | T27: =IF(O27=0,"",(O27-R27)/O27) | V27: =IF(Settings!A12="","",Settings!A12) | W27: =IF(V27="","",SUMIF($C$17:$C$36,V27,$P$17:$P$36)) | X27: =IF(OR(V27="",$P$37=0),"",W27/$P$37) | Y27: =IF(V27="","",Settings!D12) | Z27: =IF(OR(V27="",NOT(OR($B$4="Time & materials",$B$4="Staff augmentation"))),"",SUMIF($C$17:$C$36,V27,$O$17:$O$36)) | AA27: =IF(OR(Z27="",Z27=0),"",(Z27-SUMIF($C$17:$C$36,V27,$R$17:$R$36))/Z27) | AB27: =IF(AA27="","",IF(AA27>=Y27,"OK","Under floor — review rates"))
G28: =IF(M28<>"",M28,IF(L28="","",L28*Settings!$B$5*IF(F28="",1,F28))) | I28: =IF(OR(B28="",C28="",D28=""),"",IFERROR(INDEX(Settings!$B$17:$I$20,MATCH(B28,Settings!$A$17:$A$20,0),(MATCH(C28,Settings!$A$9:$A$12,0)-1)*2+IF(D28="W-2 / Employee",1,2)),"")) | J28: =IF(OR(A28="",$B$8=""),"",$B$8) | K28: =IF(OR(A28="",$B$9=""),"",$B$9) | L28: =IF(OR(A28="",IF(OR($B$14="Y",J28=""),$B$8,J28)="",IF(OR($B$14="Y",K28=""),$B$9,K28)=""),"",IFERROR(NETWORKDAYS(IF(OR($B$14="Y",J28=""),$B$8,J28),IF(OR($B$14="Y",K28=""),$B$9,K28),INDEX(Settings!$A$35:$D$74,0,MATCH(C28,Settings!$A$34:$D$34,0))),NETWORKDAYS(IF(OR($B$14="Y",J28=""),$B$8,J28),IF(OR($B$14="Y",K28=""),$B$9,K28)))) | N28: =IF(OR(C28="",D28=""),0,IFERROR(INDEX(Settings!$B$9:$C$12,MATCH(C28,Settings!$A$9:$A$12,0),IF(D28="W-2 / Employee",1,2)),0)) -> 0 | O28: =IF(OR(G28="",H28=""),0,G28*H28) -> 0 | P28: =IF(OR(G28="",I28=""),0,G28*I28) -> 0 | Q28: =P28*N28 -> 0 | R28: =P28+Q28 -> 0 | S28: =IF(C28="",0,IFERROR(INDEX(Settings!$D$9:$D$12,MATCH(C28,Settings!$A$9:$A$12,0)),0)) -> 0 | T28: =IF(O28=0,"",(O28-R28)/O28) | V28: Row GM % in the staffing table turns red when a person is under their location's resource floor (hourly types).
G29: =IF(M29<>"",M29,IF(L29="","",L29*Settings!$B$5*IF(F29="",1,F29))) | I29: =IF(OR(B29="",C29="",D29=""),"",IFERROR(INDEX(Settings!$B$17:$I$20,MATCH(B29,Settings!$A$17:$A$20,0),(MATCH(C29,Settings!$A$9:$A$12,0)-1)*2+IF(D29="W-2 / Employee",1,2)),"")) | J29: =IF(OR(A29="",$B$8=""),"",$B$8) | K29: =IF(OR(A29="",$B$9=""),"",$B$9) | L29: =IF(OR(A29="",IF(OR($B$14="Y",J29=""),$B$8,J29)="",IF(OR($B$14="Y",K29=""),$B$9,K29)=""),"",IFERROR(NETWORKDAYS(IF(OR($B$14="Y",J29=""),$B$8,J29),IF(OR($B$14="Y",K29=""),$B$9,K29),INDEX(Settings!$A$35:$D$74,0,MATCH(C29,Settings!$A$34:$D$34,0))),NETWORKDAYS(IF(OR($B$14="Y",J29=""),$B$8,J29),IF(OR($B$14="Y",K29=""),$B$9,K29)))) | N29: =IF(OR(C29="",D29=""),0,IFERROR(INDEX(Settings!$B$9:$C$12,MATCH(C29,Settings!$A$9:$A$12,0),IF(D29="W-2 / Employee",1,2)),0)) -> 0 | O29: =IF(OR(G29="",H29=""),0,G29*H29) -> 0 | P29: =IF(OR(G29="",I29=""),0,G29*I29) -> 0 | Q29: =P29*N29 -> 0 | R29: =P29+Q29 -> 0 | S29: =IF(C29="",0,IFERROR(INDEX(Settings!$D$9:$D$12,MATCH(C29,Settings!$A$9:$A$12,0)),0)) -> 0 | T29: =IF(O29=0,"",(O29-R29)/O29)
G30: =IF(M30<>"",M30,IF(L30="","",L30*Settings!$B$5*IF(F30="",1,F30))) | I30: =IF(OR(B30="",C30="",D30=""),"",IFERROR(INDEX(Settings!$B$17:$I$20,MATCH(B30,Settings!$A$17:$A$20,0),(MATCH(C30,Settings!$A$9:$A$12,0)-1)*2+IF(D30="W-2 / Employee",1,2)),"")) | J30: =IF(OR(A30="",$B$8=""),"",$B$8) | K30: =IF(OR(A30="",$B$9=""),"",$B$9) | L30: =IF(OR(A30="",IF(OR($B$14="Y",J30=""),$B$8,J30)="",IF(OR($B$14="Y",K30=""),$B$9,K30)=""),"",IFERROR(NETWORKDAYS(IF(OR($B$14="Y",J30=""),$B$8,J30),IF(OR($B$14="Y",K30=""),$B$9,K30),INDEX(Settings!$A$35:$D$74,0,MATCH(C30,Settings!$A$34:$D$34,0))),NETWORKDAYS(IF(OR($B$14="Y",J30=""),$B$8,J30),IF(OR($B$14="Y",K30=""),$B$9,K30)))) | N30: =IF(OR(C30="",D30=""),0,IFERROR(INDEX(Settings!$B$9:$C$12,MATCH(C30,Settings!$A$9:$A$12,0),IF(D30="W-2 / Employee",1,2)),0)) -> 0 | O30: =IF(OR(G30="",H30=""),0,G30*H30) -> 0 | P30: =IF(OR(G30="",I30=""),0,G30*I30) -> 0 | Q30: =P30*N30 -> 0 | R30: =P30+Q30 -> 0 | S30: =IF(C30="",0,IFERROR(INDEX(Settings!$D$9:$D$12,MATCH(C30,Settings!$A$9:$A$12,0)),0)) -> 0 | T30: =IF(O30=0,"",(O30-R30)/O30) | V30: Assignments (Staff augmentation / T&M) — type the names used in column E; month-by-month numbers per assignment are on the Forecast tab
G31: =IF(M31<>"",M31,IF(L31="","",L31*Settings!$B$5*IF(F31="",1,F31))) | I31: =IF(OR(B31="",C31="",D31=""),"",IFERROR(INDEX(Settings!$B$17:$I$20,MATCH(B31,Settings!$A$17:$A$20,0),(MATCH(C31,Settings!$A$9:$A$12,0)-1)*2+IF(D31="W-2 / Employee",1,2)),"")) | J31: =IF(OR(A31="",$B$8=""),"",$B$8) | K31: =IF(OR(A31="",$B$9=""),"",$B$9) | L31: =IF(OR(A31="",IF(OR($B$14="Y",J31=""),$B$8,J31)="",IF(OR($B$14="Y",K31=""),$B$9,K31)=""),"",IFERROR(NETWORKDAYS(IF(OR($B$14="Y",J31=""),$B$8,J31),IF(OR($B$14="Y",K31=""),$B$9,K31),INDEX(Settings!$A$35:$D$74,0,MATCH(C31,Settings!$A$34:$D$34,0))),NETWORKDAYS(IF(OR($B$14="Y",J31=""),$B$8,J31),IF(OR($B$14="Y",K31=""),$B$9,K31)))) | N31: =IF(OR(C31="",D31=""),0,IFERROR(INDEX(Settings!$B$9:$C$12,MATCH(C31,Settings!$A$9:$A$12,0),IF(D31="W-2 / Employee",1,2)),0)) -> 0 | O31: =IF(OR(G31="",H31=""),0,G31*H31) -> 0 | P31: =IF(OR(G31="",I31=""),0,G31*I31) -> 0 | Q31: =P31*N31 -> 0 | R31: =P31+Q31 -> 0 | S31: =IF(C31="",0,IFERROR(INDEX(Settings!$D$9:$D$12,MATCH(C31,Settings!$A$9:$A$12,0)),0)) -> 0 | T31: =IF(O31=0,"",(O31-R31)/O31) | V31: Assignment / project | W31: People
G32: =IF(M32<>"",M32,IF(L32="","",L32*Settings!$B$5*IF(F32="",1,F32))) | I32: =IF(OR(B32="",C32="",D32=""),"",IFERROR(INDEX(Settings!$B$17:$I$20,MATCH(B32,Settings!$A$17:$A$20,0),(MATCH(C32,Settings!$A$9:$A$12,0)-1)*2+IF(D32="W-2 / Employee",1,2)),"")) | J32: =IF(OR(A32="",$B$8=""),"",$B$8) | K32: =IF(OR(A32="",$B$9=""),"",$B$9) | L32: =IF(OR(A32="",IF(OR($B$14="Y",J32=""),$B$8,J32)="",IF(OR($B$14="Y",K32=""),$B$9,K32)=""),"",IFERROR(NETWORKDAYS(IF(OR($B$14="Y",J32=""),$B$8,J32),IF(OR($B$14="Y",K32=""),$B$9,K32),INDEX(Settings!$A$35:$D$74,0,MATCH(C32,Settings!$A$34:$D$34,0))),NETWORKDAYS(IF(OR($B$14="Y",J32=""),$B$8,J32),IF(OR($B$14="Y",K32=""),$B$9,K32)))) | N32: =IF(OR(C32="",D32=""),0,IFERROR(INDEX(Settings!$B$9:$C$12,MATCH(C32,Settings!$A$9:$A$12,0),IF(D32="W-2 / Employee",1,2)),0)) -> 0 | O32: =IF(OR(G32="",H32=""),0,G32*H32) -> 0 | P32: =IF(OR(G32="",I32=""),0,G32*I32) -> 0 | Q32: =P32*N32 -> 0 | R32: =P32+Q32 -> 0 | S32: =IF(C32="",0,IFERROR(INDEX(Settings!$D$9:$D$12,MATCH(C32,Settings!$A$9:$A$12,0)),0)) -> 0 | T32: =IF(O32=0,"",(O32-R32)/O32) | W32: =IF(V32="","",COUNTIFS($E$17:$E$36,V32,$A$17:$A$36,"<>"))
G33: =IF(M33<>"",M33,IF(L33="","",L33*Settings!$B$5*IF(F33="",1,F33))) | I33: =IF(OR(B33="",C33="",D33=""),"",IFERROR(INDEX(Settings!$B$17:$I$20,MATCH(B33,Settings!$A$17:$A$20,0),(MATCH(C33,Settings!$A$9:$A$12,0)-1)*2+IF(D33="W-2 / Employee",1,2)),"")) | J33: =IF(OR(A33="",$B$8=""),"",$B$8) | K33: =IF(OR(A33="",$B$9=""),"",$B$9) | L33: =IF(OR(A33="",IF(OR($B$14="Y",J33=""),$B$8,J33)="",IF(OR($B$14="Y",K33=""),$B$9,K33)=""),"",IFERROR(NETWORKDAYS(IF(OR($B$14="Y",J33=""),$B$8,J33),IF(OR($B$14="Y",K33=""),$B$9,K33),INDEX(Settings!$A$35:$D$74,0,MATCH(C33,Settings!$A$34:$D$34,0))),NETWORKDAYS(IF(OR($B$14="Y",J33=""),$B$8,J33),IF(OR($B$14="Y",K33=""),$B$9,K33)))) | N33: =IF(OR(C33="",D33=""),0,IFERROR(INDEX(Settings!$B$9:$C$12,MATCH(C33,Settings!$A$9:$A$12,0),IF(D33="W-2 / Employee",1,2)),0)) -> 0 | O33: =IF(OR(G33="",H33=""),0,G33*H33) -> 0 | P33: =IF(OR(G33="",I33=""),0,G33*I33) -> 0 | Q33: =P33*N33 -> 0 | R33: =P33+Q33 -> 0 | S33: =IF(C33="",0,IFERROR(INDEX(Settings!$D$9:$D$12,MATCH(C33,Settings!$A$9:$A$12,0)),0)) -> 0 | T33: =IF(O33=0,"",(O33-R33)/O33) | W33: =IF(V33="","",COUNTIFS($E$17:$E$36,V33,$A$17:$A$36,"<>"))
G34: =IF(M34<>"",M34,IF(L34="","",L34*Settings!$B$5*IF(F34="",1,F34))) | I34: =IF(OR(B34="",C34="",D34=""),"",IFERROR(INDEX(Settings!$B$17:$I$20,MATCH(B34,Settings!$A$17:$A$20,0),(MATCH(C34,Settings!$A$9:$A$12,0)-1)*2+IF(D34="W-2 / Employee",1,2)),"")) | J34: =IF(OR(A34="",$B$8=""),"",$B$8) | K34: =IF(OR(A34="",$B$9=""),"",$B$9) | L34: =IF(OR(A34="",IF(OR($B$14="Y",J34=""),$B$8,J34)="",IF(OR($B$14="Y",K34=""),$B$9,K34)=""),"",IFERROR(NETWORKDAYS(IF(OR($B$14="Y",J34=""),$B$8,J34),IF(OR($B$14="Y",K34=""),$B$9,K34),INDEX(Settings!$A$35:$D$74,0,MATCH(C34,Settings!$A$34:$D$34,0))),NETWORKDAYS(IF(OR($B$14="Y",J34=""),$B$8,J34),IF(OR($B$14="Y",K34=""),$B$9,K34)))) | N34: =IF(OR(C34="",D34=""),0,IFERROR(INDEX(Settings!$B$9:$C$12,MATCH(C34,Settings!$A$9:$A$12,0),IF(D34="W-2 / Employee",1,2)),0)) -> 0 | O34: =IF(OR(G34="",H34=""),0,G34*H34) -> 0 | P34: =IF(OR(G34="",I34=""),0,G34*I34) -> 0 | Q34: =P34*N34 -> 0 | R34: =P34+Q34 -> 0 | S34: =IF(C34="",0,IFERROR(INDEX(Settings!$D$9:$D$12,MATCH(C34,Settings!$A$9:$A$12,0)),0)) -> 0 | T34: =IF(O34=0,"",(O34-R34)/O34) | W34: =IF(V34="","",COUNTIFS($E$17:$E$36,V34,$A$17:$A$36,"<>"))
G35: =IF(M35<>"",M35,IF(L35="","",L35*Settings!$B$5*IF(F35="",1,F35))) | I35: =IF(OR(B35="",C35="",D35=""),"",IFERROR(INDEX(Settings!$B$17:$I$20,MATCH(B35,Settings!$A$17:$A$20,0),(MATCH(C35,Settings!$A$9:$A$12,0)-1)*2+IF(D35="W-2 / Employee",1,2)),"")) | J35: =IF(OR(A35="",$B$8=""),"",$B$8) | K35: =IF(OR(A35="",$B$9=""),"",$B$9) | L35: =IF(OR(A35="",IF(OR($B$14="Y",J35=""),$B$8,J35)="",IF(OR($B$14="Y",K35=""),$B$9,K35)=""),"",IFERROR(NETWORKDAYS(IF(OR($B$14="Y",J35=""),$B$8,J35),IF(OR($B$14="Y",K35=""),$B$9,K35),INDEX(Settings!$A$35:$D$74,0,MATCH(C35,Settings!$A$34:$D$34,0))),NETWORKDAYS(IF(OR($B$14="Y",J35=""),$B$8,J35),IF(OR($B$14="Y",K35=""),$B$9,K35)))) | N35: =IF(OR(C35="",D35=""),0,IFERROR(INDEX(Settings!$B$9:$C$12,MATCH(C35,Settings!$A$9:$A$12,0),IF(D35="W-2 / Employee",1,2)),0)) -> 0 | O35: =IF(OR(G35="",H35=""),0,G35*H35) -> 0 | P35: =IF(OR(G35="",I35=""),0,G35*I35) -> 0 | Q35: =P35*N35 -> 0 | R35: =P35+Q35 -> 0 | S35: =IF(C35="",0,IFERROR(INDEX(Settings!$D$9:$D$12,MATCH(C35,Settings!$A$9:$A$12,0)),0)) -> 0 | T35: =IF(O35=0,"",(O35-R35)/O35) | W35: =IF(V35="","",COUNTIFS($E$17:$E$36,V35,$A$17:$A$36,"<>"))
G36: =IF(M36<>"",M36,IF(L36="","",L36*Settings!$B$5*IF(F36="",1,F36))) | I36: =IF(OR(B36="",C36="",D36=""),"",IFERROR(INDEX(Settings!$B$17:$I$20,MATCH(B36,Settings!$A$17:$A$20,0),(MATCH(C36,Settings!$A$9:$A$12,0)-1)*2+IF(D36="W-2 / Employee",1,2)),"")) | J36: =IF(OR(A36="",$B$8=""),"",$B$8) | K36: =IF(OR(A36="",$B$9=""),"",$B$9) | L36: =IF(OR(A36="",IF(OR($B$14="Y",J36=""),$B$8,J36)="",IF(OR($B$14="Y",K36=""),$B$9,K36)=""),"",IFERROR(NETWORKDAYS(IF(OR($B$14="Y",J36=""),$B$8,J36),IF(OR($B$14="Y",K36=""),$B$9,K36),INDEX(Settings!$A$35:$D$74,0,MATCH(C36,Settings!$A$34:$D$34,0))),NETWORKDAYS(IF(OR($B$14="Y",J36=""),$B$8,J36),IF(OR($B$14="Y",K36=""),$B$9,K36)))) | N36: =IF(OR(C36="",D36=""),0,IFERROR(INDEX(Settings!$B$9:$C$12,MATCH(C36,Settings!$A$9:$A$12,0),IF(D36="W-2 / Employee",1,2)),0)) -> 0 | O36: =IF(OR(G36="",H36=""),0,G36*H36) -> 0 | P36: =IF(OR(G36="",I36=""),0,G36*I36) -> 0 | Q36: =P36*N36 -> 0 | R36: =P36+Q36 -> 0 | S36: =IF(C36="",0,IFERROR(INDEX(Settings!$D$9:$D$12,MATCH(C36,Settings!$A$9:$A$12,0)),0)) -> 0 | T36: =IF(O36=0,"",(O36-R36)/O36) | W36: =IF(V36="","",COUNTIFS($E$17:$E$36,V36,$A$17:$A$36,"<>"))
A37: Staffing total | G37: =SUM(G17:G36) -> 0 | O37: =SUM(O17:O36) -> 0 | P37: =SUM(P17:P36) -> 0 | Q37: =SUM(Q17:Q36) -> 0 | R37: =SUM(R17:R36) -> 0 | T37: =IF(O37=0,"",(O37-R37)/O37) | W37: =IF(V37="","",COUNTIFS($E$17:$E$36,V37,$A$17:$A$36,"<>"))
W38: =IF(V38="","",COUNTIFS($E$17:$E$36,V38,$A$17:$A$36,"<>"))
A39: Additional costs — travel, meals, licences, hardware, subcontractors (required when B13 = Y). To remove one, clear its yellow cells. | W39: =IF(V39="","",COUNTIFS($E$17:$E$36,V39,$A$17:$A$36,"<>"))
A40: Description * | B40: Category * | C40: Location | D40: Amount * | E40: Frequency (dropdown: One-time or Monthly; blank = One-time) | F40: Billed to client? * (dropdown Y/N — required) | G40: Total cost counted | H40: Revenue counted (pass-through) | I40: Check | V40: Unassigned (blank column E) | W40: =COUNTIFS($E$17:$E$36,"",$A$17:$A$36,"<>") -> 0
...

Sheet Settings
A1: Settings
A2: Yellow cells are yours to set. Everything on the Cost Margin, Monthly and Forecast tabs reads from here.
A4: 1 · General
A5: Hours per working day | B5: 8 | C5: Hours = working days (Mon–Fri minus the location's holidays) × hours/day × utilization.
A6: Project GM floor % | B6: 0.35 | C6: The project passes when its overall GM is at or above this. Each location also has its own resource-level floor below (US 35%, India 50%) — shown as a check, not a fail.
A7: 2 · Burden % and GM floor by location
A8: Location | B8: Burden % — W-2 / Employee | C8: Burden % — 1099 / Contractor | D8: Resource GM floor % | E8: Note
A9: US | B9: 0.36 | C9: 0.05 | D9: 0.35 | E9: US W-2 36%, US 1099 5% — per Kanna, 2026-10-11.
A10: India | B10: 0.08 | C10: 0.08 | D10: 0.5 | E10: All India resources 8% — per Kanna, 2026-10-11.
E11: Add a third location here; it appears in every dropdown, the rate card and the holiday table.
A13: Burden cost = labour cost × the burden % for the person's Location and Employment type. Resource GM floor = what each location's people should earn on hourly work (US 35%, India 50%).
A15: 3 · Cost rate card — OUR hourly cost per person before burden, by seniority, location and employment type (PLACEHOLDERS — set your real numbers)
A16: Seniority | B16: =IF($A$9="","",$A$9&" · "&"W-2 / Employee") -> US · W-2 / Employee | C16: =IF($A$9="","",$A$9&" · "&"1099 / Contractor") -> US · 1099 / Contractor | D16: =IF($A$10="","",$A$10&" · "&"W-2 / Employee") -> India · W-2 / Employee | E16: =IF($A$10="","",$A$10&" · "&"1099 / Contractor") -> India · 1099 / Contractor | F16: =IF($A$11="","",$A$11&" · "&"W-2 / Employee") | G16: =IF($A$11="","",$A$11&" · "&"1099 / Contractor") | H16: =IF($A$12="","",$A$12&" · "&"W-2 / Employee") | I16: =IF($A$12="","",$A$12&" · "&"1099 / Contractor")
A17: Junior | B17: 60 | C17: 65 | D17: 12 | E17: 14
A18: Mid | B18: 80 | C18: 88 | D18: 18 | E18: 20
A19: Senior | B19: 100 | C19: 110 | D19: 25 | E19: 28
A20: Principal | B20: 130 | C20: 145 | D20: 35 | E20: 40
A21: A staffing row's cost/hour is pre-filled from here by Seniority × Location × Employment type. Typing a value on the row overrides it.
A23: 4 · Lists
C24: Employment types | E24: Engagement types | G24: Cost categories
A25: Seniority levels are the rate-card rows above (A17:A20). | C25: W-2 / Employee | E25: Fixed cost | F25: Fixed cost / Assessment: one total price. MSP: fixed fee per month. Time & materials: hours × bill rate. Staff augmentation: pure staffing — each resource has their own bill rate, cost, dates and assignment. | G25: Travel
C26: 1099 / Contractor | E26: Assessment | G26: Lodging
E27: MSP | G27: Meals
E28: Time & materials | G28: Software / licences
E29: Staff augmentation | G29: Hardware
G30: Subcontractor
G31: Miscellaneous
A33: 5 · Holidays by location — weekday holidays only; the header is the location name
A34: =IF($A$9="","",$A$9) -> US | B34: =IF($A$10="","",$A$10) -> India | C34: =IF($A$11="","",$A$11) | D34: =IF($A$12="","",$A$12)
A35: 46023 | B35: 46023 | F35: US = federal holidays 2026–27 (observed). India = national days only (Republic Day, Independence Day, Gandhi Jayanti, Jan 1, Dec 25); add Holi, Diwali and state/company days from your HR calendar. Rows run to 74.
A36: 46041 | B36: 46048
A37: 46069 | B37: 46249
A38: 46167 | B38: 46297
A39: 46192 | B39: 46381
A40: 46206 | B40: 46388
A41: 46272 | B41: 46413
A42: 46307 | B42: 46614
A43: 46337 | B43: 46662
A44: 46352 | B44: 46746
A45: 46381
...

Sheet Monthly
A1: Month by month — people, revenue, cost and margin
A2: Built from the Cost Margin tab. Up to 24 months. Partial months are prorated by days (row 4). MSP revenue = fee × share of month; Fixed cost / Assessment = price spread by share of month; T&M / Staff augmentation = each resource's hours that month × their bill rate (see the per-person grids). One-time costs land in month 1; monthly ones repeat, prorated.
A3: =IF('Cost Margin'!$B$10="","Fill engagement type and project dates on the Cost Margin tab.",IF('Cost Margin'!$B$10>2,"Monthly view REQUIRED — this engagement runs "&TEXT('Cost Margin'!$B$10,"0.0")&" months.","Not needed — this engagement is "&TEXT('Cost Margin'!$B$10,"0.0")&" month(s). Use the Cost Margin summary; everything below is greyed out.")) -> Fill engagement type and project dates on the Cost Margin tab.
A4: Share of month covered | C4: =IF(C5="","",(C6-C5+1)/DAY(EOMONTH(C5,0))) | D4: =IF(D5="","",(D6-D5+1)/DAY(EOMONTH(D5,0))) | E4: =IF(E5="","",(E6-E5+1)/DAY(EOMONTH(E5,0))) | F4: =IF(F5="","",(F6-F5+1)/DAY(EOMONTH(F5,0))) | G4: =IF(G5="","",(G6-G5+1)/DAY(EOMONTH(G5,0))) | H4: =IF(H5="","",(H6-H5+1)/DAY(EOMONTH(H5,0))) | I4: =IF(I5="","",(I6-I5+1)/DAY(EOMONTH(I5,0))) | J4: =IF(J5="","",(J6-J5+1)/DAY(EOMONTH(J5,0))) | ... Z4: =IF(Z5="","",(Z6-Z5+1)/DAY(EOMONTH(Z5,0)))
A5: Month start | B5: =IF(OR('Cost Margin'!$B$8="",'Cost Margin'!$B$9=""),"",(YEAR('Cost Margin'!$B$9)-YEAR('Cost Margin'!$B$8))*12+MONTH('Cost Margin'!$B$9)-MONTH('Cost Margin'!$B$8)+1) | C5: =IF('Cost Margin'!$B$8="","",'Cost Margin'!$B$8) | D5: =IF(OR($C$5="",$B$5="",1>=$B$5),"",EOMONTH($C$5,0)+1) | E5: =IF(OR($C$5="",$B$5="",2>=$B$5),"",EOMONTH($C$5,1)+1) | F5: =IF(OR($C$5="",$B$5="",3>=$B$5),"",EOMONTH($C$5,2)+1) | G5: =IF(OR($C$5="",$B$5="",4>=$B$5),"",EOMONTH($C$5,3)+1) | H5: =IF(OR($C$5="",$B$5="",5>=$B$5),"",EOMONTH($C$5,4)+1) | I5: =IF(OR($C$5="",$B$5="",6>=$B$5),"",EOMONTH($C$5,5)+1) | J5: =IF(OR($C$5="",$B$5="",7>=$B$5),"",EOMONTH($C$5,6)+1) | K5: =IF(OR($C$5="",$B$5="",8>=$B$5),"",EOMONTH($C$5,7)+1) | L5: =IF(OR($C$5="",$B$5="",9>=$B$5),"",EOMONTH($C$5,8)+1) | M5: =IF(OR($C$5="",$B$5="",10>=$B$5),"",EOMONTH($C$5,9)+1) | N5: =IF(OR($C$5="",$B$5="",11>=$B$5),"",EOMONTH($C$5,10)+1) | O5: =IF(OR($C$5="",$B$5="",12>=$B$5),"",EOMONTH($C$5,11)+1) | P5: =IF(OR($C$5="",$B$5="",13>=$B$5),"",EOMONTH($C$5,12)+1) | Q5: =IF(OR($C$5="",$B$5="",14>=$B$5),"",EOMONTH($C$5,13)+1) | R5: =IF(OR($C$5="",$B$5="",15>=$B$5),"",EOMONTH($C$5,14)+1) | S5: =IF(OR($C$5="",$B$5="",16>=$B$5),"",EOMONTH($C$5,15)+1) | T5: =IF(OR($C$5="",$B$5="",17>=$B$5),"",EOMONTH($C$5,16)+1) | U5: =IF(OR($C$5="",$B$5="",18>=$B$5),"",EOMONTH($C$5,17)+1) | V5: =IF(OR($C$5="",$B$5="",19>=$B$5),"",EOMONTH($C$5,18)+1) | W5: =IF(OR($C$5="",$B$5="",20>=$B$5),"",EOMONTH($C$5,19)+1) | X5: =IF(OR($C$5="",$B$5="",21>=$B$5),"",EOMONTH($C$5,20)+1) | Y5: =IF(OR($C$5="",$B$5="",22>=$B$5),"",EOMONTH($C$5,21)+1) | Z5: =IF(OR($C$5="",$B$5="",23>=$B$5),"",EOMONTH($C$5,22)+1)
A6: Month end | B6: ← calendar months in view | C6: =IF(C5="","",MIN(EOMONTH(C5,0),'Cost Margin'!$B$9)) | D6: =IF(D5="","",MIN(EOMONTH(D5,0),'Cost Margin'!$B$9)) | E6: =IF(E5="","",MIN(EOMONTH(E5,0),'Cost Margin'!$B$9)) | F6: =IF(F5="","",MIN(EOMONTH(F5,0),'Cost Margin'!$B$9)) | G6: =IF(G5="","",MIN(EOMONTH(G5,0),'Cost Margin'!$B$9)) | H6: =IF(H5="","",MIN(EOMONTH(H5,0),'Cost Margin'!$B$9)) | I6: =IF(I5="","",MIN(EOMONTH(I5,0),'Cost Margin'!$B$9)) | J6: =IF(J5="","",MIN(EOMONTH(J5,0),'Cost Margin'!$B$9)) | ... Z6: =IF(Z5="","",MIN(EOMONTH(Z5,0),'Cost Margin'!$B$9))
A7: Row | B7: Person / line | C7: =IF(C5="","",TEXT(C5,"mmm yyyy")) | D7: =IF(D5="","",TEXT(D5,"mmm yyyy")) | E7: =IF(E5="","",TEXT(E5,"mmm yyyy")) | F7: =IF(F5="","",TEXT(F5,"mmm yyyy")) | G7: =IF(G5="","",TEXT(G5,"mmm yyyy")) | H7: =IF(H5="","",TEXT(H5,"mmm yyyy")) | I7: =IF(I5="","",TEXT(I5,"mmm yyyy")) | J7: =IF(J5="","",TEXT(J5,"mmm yyyy")) | ... Z7: =IF(Z5="","",TEXT(Z5,"mmm yyyy")) | AA7: Project total
A8: Working days in month, per person | AB8: Assignment
A9: 1 | B9: =IF('Cost Margin'!A17="","",'Cost Margin'!A17&IF('Cost Margin'!E17="",""," · "&'Cost Margin'!E17)) | C9: =IF(OR(C$5="",'Cost Margin'!$A17="",IF(OR('Cost Margin'!$B$14="Y",'Cost Margin'!$J17=""),'Cost Margin'!$B$8,'Cost Margin'!$J17)="",IF(OR('Cost Margin'!$B$14="Y",'Cost Margin'!$K17=""),'Cost Margin'!$B$9,'Cost Margin'!$K17)=""),0,IF(MIN(IF(OR('Cost Margin'!$B$14="Y",'Cost Margin'!$K17=""),'Cost Margin'!$B$9,'Cost Margin'!$K17),C$6)<MAX(IF(OR('Cost Margin'!$B$14="Y",'Cost Margin'!$J17=""),'Cost Margin'!$B$8,'Cost Margin'!$J17),C$5),0,IFERROR(NETWORKDAYS(MAX(IF(OR('Cost Margin'!$B$14="Y",'Cost Margin'!$J17=""),'Cost Margin'!$B$8,'Cost Margin'!$J17),C$5),MIN(IF(OR('Cost Margin'!$B$14="Y",'Cost Margin'!$K17=""),'Cost Margin'!$B$9,'Cost Margin'!$K17),C$6),INDEX(Settings!$A$35:$D$74,0,MATCH('Cost Margin'!$C17,Settings!$A$34:$D$34,0))),NETWORKDAYS(MAX(IF(OR('Cost Margin'!$B$14="Y",'Cost Margin'!$J17=""),'Cost Margin'!$B$8,'Cost Margin'!$J17),C$5),MIN(IF(OR('Cost Margin'!$B$14="Y",'Cost Margin'!$K17=""),'Cost Margin'!$B$9,'Cost Margin'!$K17),C$6))))) -> 0 | D9: =IF(OR(D$5="",'Cost Margin'!$A17="",IF(OR('Cost Margin'!$B$14="Y",'Cost Margin'!$J17=""),'Cost Margin'!$B$8,'Cost Margin'!$J17)="",IF(OR('Cost Margin'!$B$14="Y",'Cost Margin'!$K17=""),'Cost Margin'!$B$9,'Cost Margin'!$K17)=""),0,IF(MIN(IF(OR('Cost Margin'!$B$14="Y",'Cost Margin'!$K17=""),'Cost Margin'!$B$9,'Cost Margin'!$K17),D$6)<MAX(IF(OR('Cost Margin'!$B$14="Y",'Cost Margin'!$J17=""),'Cost Margin'!$B$8,'Cost Margin'!$J17),D$5),0,IFERROR(NETWORKDAYS(MAX(IF(OR('Cost Margin'!$B$14="Y",'Cost Margin'!$J17=""),'Cost Margin'!$B$8,'Cost Margin'!$J17),D$5),MIN(IF(OR('Cost Margin'!$B$14="Y",'Cost Margin'!$K17=""),'Cost Margin'!$B$9,'Cost Margin'!$K17),D$6),INDEX(Settings!$A$35:$D$74,0,MATCH('Cost Margin'!$C17,Settings!$A$34:$D$34,0))),NETWORKDAYS(MAX(IF(OR('Cost Margin'!$B$14="Y",'Cost Margin'!$J17=""),'Cost Margin'!$B$8,'Cost Margin'!$J17),D$5),MIN(IF(OR('Cost Margin'!$B$14="Y",'Cost Margin'!$K17=""),'Cost Margin'!$B$9,'Cost Margin'!$K17),D$6))))) -> 0 | E9: =IF(OR(E$5="",'Cost Margin'!$A17="",IF(OR('Cost Margin'!$B$14="Y",'Cost Margin'!$J17=""),'Cost Margin'!$B$8,'Cost Margin'!$J17)="",IF(OR('Cost Margin'!$B$14="Y",'Cost Margin'!$K17=""),'Cost Margin'!$B$9,'Cost Margin'!$K17)=""),0,IF(MIN(IF(OR('Cost Margin'!$B$14="Y",'Cost Margin'!$K17=""),'Cost Margin'!$B$9,'Cost Margin'!$K17),E$6)<MAX(IF(OR('Cost Margin'!$B$14="Y",'Cost Margin'!$J17=""),'Cost Margin'!$B$8,'Cost Margin'!$J17),E$5),0,IFERROR(NETWORKDAYS(MAX(IF(OR('Cost Margin'!$B$14="Y",'Cost Margin'!$J17=""),'Cost Margin'!$B$8,'Cost Margin'!$J17),E$5),MIN(IF(OR('Cost Margin'!$B$14="Y",'Cost Margin'!$K17=""),'Cost Margin'!$B$9,'Cost Margin'!$K17),E$6),INDEX(Settings!$A$35:$D$74,0,MATCH('Cost Margin'!$C17,Settings!$A$34:$D$34,0))),NETWORKDAYS(MAX(IF(OR('Cost Margin'!$B$14="Y",'Cost Margin'!$J17=""),'Cost Margin'!$B$8,'Cost Margin'!$J17),E$5),MIN(IF(OR('Cost Margin'!$B$14="Y",'Cost Margin'!$K17=""),'Cost Margin'!$B$9,'Cost Margin'!$K17),E$6))))) -> 0 | F9: =IF(OR(F$5="",'Cost Margin'!$A17="",IF(OR('Cost Margin'!$B$14="Y",'Cost Margin'!$J17=""),'Cost Margin'!$B$8,'Cost Margin'!$J17)="",IF(OR('Cost Margin'!$B$14="Y",'Cost Margin'!$K17=""),'Cost Margin'!$B$9,'Cost Margin'!$K17)=""),0,IF(MIN(IF(OR('Cost Margin'!$B$14="Y",'Cost Margin'!$K17=""),'Cost Margin'!$B$9,'Cost Margin'!$K17),F$6)<MAX(IF(OR('Cost Margin'!$B$14="Y",'Cost Margin'!$J17=""),'Cost Margin'!$B$8,'Cost Margin'!$J17),F$5),0,IFERROR(NETWORKDAYS(MAX(IF(OR('Cost Margin'!$B$14="Y",'Cost Margin'!$J17=""),'Cost Margin'!$B$8,'Cost Margin'!$J17),F$5),MIN(IF(OR('Cost Margin'!$B$14="Y",'Cost Margin'!$K17=""),'Cost Margin'!$B$9,'Cost Margin'!$K17),F$6),INDEX(Settings!$A$35:$D$74,0,MATCH('Cost Margin'!$C17,Settings!$A$34:$D$34,0))),NETWORKDAYS(MAX(IF(OR('Cost Margin'!$B$14="Y",'Cost Margin'!$J17=""),'Cost Margin'!$B$8,'Cost Margin'!$J17),F$5),MIN(IF(OR('Cost Margin'!$B$14="Y",'Cost Margin'!$K17=""),'Cost Margin'!$B$9,'Cost Margin'!$K17),F$6))))) -> 0 | G9: =IF(OR(G$5="",'Cost Margin'!$A17="",IF(OR('Cost Margin'!$B$14="Y",'Cost Margin'!$J17=""),'Cost Margin'!$B$8,'Cost Margin'!$J17)="",IF(OR('Cost Margin'!$B$14="Y",'Cost Margin'!$K17=""),'Cost Margin'!$B$9,'Cost Margin'!$K17)=""),0,IF(MIN(IF(OR('Cost Margin'!$B$14="Y",'Cost Margin'!$K17=""),'Cost Margin'!$B$9,'Cost Margin'!$K17),G$6)<MAX(IF(OR('Cost Margin'!$B$14="Y",'Cost Margin'!$J17=""),'Cost Margin'!$B$8,'Cost Margin'!$J17),G$5),0,IFERROR(NETWORKDAYS(MAX(IF(OR('Cost Margin'!$B$14="Y",'Cost Margin'!$J17=""),'Cost Margin'!$B$8,'Cost Margin'!$J17),G$5),MIN(IF(OR('Cost Margin'!$B$14="Y",'Cost Margin'!$K17=""),'Cost Margin'!$B$9,'Cost Margin'!$K17),G$6),INDEX(Settings!$A$35:$D$74,0,MATCH('Cost Margin'!$C17,Settings!$A$34:$D$34,0))),NETWORKDAYS(MAX(IF(OR('Cost Margin'!$B$14="Y",'Cost Margin'!$J17=""),'Cost Margin'!$B$8,'Cost Margin'!$J17),G$5),MIN(IF(OR('Cost Margin'!$B$14="Y",'Cost Margin'!$K17=""),'Cost Margin'!$B$9,'Cost Margin'!$K17),G$6))))) -> 0 | H9: =IF(OR(H$5="",'Cost Margin'!$A17="",IF(OR('Cost Margin'!$B$14="Y",'Cost Margin'!$J17=""),'Cost Margin'!$B$8,'Cost Margin'!$J17)="",IF(OR('Cost Margin'!$B$14="Y",'Cost Margin'!$K17=""),'Cost Margin'!$B$9,'Cost Margin'!$K17)=""),0,IF(MIN(IF(OR('Cost Margin'!$B$14="Y",'Cost Margin'!$K17=""),'Cost Margin'!$B$9,'Cost Margin'!$K17),H$6)<MAX(IF(OR('Cost Margin'!$B$14="Y",'Cost Margin'!$J17=""),'Cost Margin'!$B$8,'Cost Margin'!$J17),H$5),0,IFERROR(NETWORKDAYS(MAX(IF(OR('Cost Margin'!$B$14="Y",'Cost Margin'!$J17=""),'Cost Margin'!$B$8,'Cost Margin'!$J17),H$5),MIN(IF(OR('Cost Margin'!$B$14="Y",'Cost Margin'!$K17=""),'Cost Margin'!$B$9,'Cost Margin'!$K17),H$6),INDEX(Settings!$A$35:$D$74,0,MATCH('Cost Margin'!$C17,Settings!$A$34:$D$34,0))),NETWORKDAYS(MAX(IF(OR('Cost Margin'!$B$14="Y",'Cost Margin'!$J17=""),'Cost Margin'!$B$8,'Cost Margin'!$J17),H$5),MIN(IF(OR('Cost Margin'!$B$14="Y",'Cost Margin'!$K17=""),'Cost Margin'!$B$9,'Cost Margin'!$K17),H$6))))) -> 0 | I9: =IF(OR(I$5="",'Cost Margin'!$A17="",IF(OR('Cost Margin'!$B$14="Y",'Cost Margin'!$J17=""),'Cost Margin'!$B$8,'Cost Margin'!$J17)="",IF(OR('Cost Margin'!$B$14="Y",'Cost Margin'!$K17=""),'Cost Margin'!$B$9,'Cost Margin'!$K17)=""),0,IF(MIN(IF(OR('Cost Margin'!$B$14="Y",'Cost Margin'!$K17=""),'Cost Margin'!$B$9,'Cost Margin'!$K17),I$6)<MAX(IF(OR('Cost Margin'!$B$14="Y",'Cost Margin'!$J17=""),'Cost Margin'!$B$8,'Cost Margin'!$J17),I$5),0,IFERROR(NETWORKDAYS(MAX(IF(OR('Cost Margin'!$B$14="Y",'Cost Margin'!$J17=""),'Cost Margin'!$B$8,'Cost Margin'!$J17),I$5),MIN(IF(OR('Cost Margin'!$B$14="Y",'Cost Margin'!$K17=""),'Cost Margin'!$B$9,'Cost Margin'!$K17),I$6),INDEX(Settings!$A$35:$D$74,0,MATCH('Cost Margin'!$C17,Settings!$A$34:$D$34,0))),NETWORKDAYS(MAX(IF(OR('Cost Margin'!$B$14="Y",'Cost Margin'!$J17=""),'Cost Margin'!$B$8,'Cost Margin'!$J17),I$5),MIN(IF(OR('Cost Margin'!$B$14="Y",'Cost Margin'!$K17=""),'Cost Margin'!$B$9,'Cost Margin'!$K17),I$6))))) -> 0 | J9: =IF(OR(J$5="",'Cost Margin'!$A17="",IF(OR('Cost Margin'!$B$14="Y",'Cost Margin'!$J17=""),'Cost Margin'!$B$8,'Cost Margin'!$J17)="",IF(OR('Cost Margin'!$B$14="Y",'Cost Margin'!$K17=""),'Cost Margin'!$B$9,'Cost Margin'!$K17)=""),0,IF(MIN(IF(OR('Cost Margin'!$B$14="Y",'Cost Margin'!$K17=""),'Cost Margin'!$B$9,'Cost Margin'!$K17),J$6)<MAX(IF(OR('Cost Margin'!$B$14="Y",'Cost Margin'!$J17=""),'Cost Margin'!$B$8,'Cost Margin'!$J17),J$5),0,IFERROR(NETWORKDAYS(MAX(IF(OR('Cost Margin'!$B$14="Y",'Cost Margin'!$J17=""),'Cost Margin'!$B$8,'Cost Margin'!$J17),J$5),MIN(IF(OR('Cost Margin'!$B$14="Y",'Cost Margin'!$K17=""),'Cost Margin'!$B$9,'Cost Margin'!$K17),J$6),INDEX(Settings!$A$35:$D$74,0,MATCH('Cost Margin'!$C17,Settings!$A$34:$D$34,0))),NETWORKDAYS(MAX(IF(OR('Cost Margin'!$B$14="Y",'Cost Margin'!$J17=""),'Cost Margin'!$B$8,'Cost Margin'!$J17),J$5),MIN(IF(OR('Cost Margin'!$B$14="Y",'Cost Margin'!$K17=""),'Cost Margin'!$B$9,'Cost Margin'!$K17),J$6))))) -> 0 | ... Z9: =IF(OR(Z$5="",'Cost Margin'!$A17="",IF(OR('Cost Margin'!$B$14="Y",'Cost Margin'!$J17=""),'Cost Margin'!$B$8,'Cost Margin'!$J17)="",IF(OR('Cost Margin'!$B$14="Y",'Cost Margin'!$K17=""),'Cost Margin'!$B$9,'Cost Margin'!$K17)=""),0,IF(MIN(IF(OR('Cost Margin'!$B$14="Y",'Cost Margin'!$K17=""),'Cost Margin'!$B$9,'Cost Margin'!$K17),Z$6)<MAX(IF(OR('Cost Margin'!$B$14="Y",'Cost Margin'!$J17=""),'Cost Margin'!$B$8,'Cost Margin'!$J17),Z$5),0,IFERROR(NETWORKDAYS(MAX(IF(OR('Cost Margin'!$B$14="Y",'Cost Margin'!$J17=""),'Cost Margin'!$B$8,'Cost Margin'!$J17),Z$5),MIN(IF(OR('Cost Margin'!$B$14="Y",'Cost Margin'!$K17=""),'Cost Margin'!$B$9,'Cost Margin'!$K17),Z$6),INDEX(Settings!$A$35:$D$74,0,MATCH('Cost Margin'!$C17,Settings!$A$34:$D$34,0))),NETWORKDAYS(MAX(IF(OR('Cost Margin'!$B$14="Y",'Cost Margin'!$J17=""),'Cost Margin'!$B$8,'Cost Margin'!$J17),Z$5),MIN(IF(OR('Cost Margin'!$B$14="Y",'Cost Margin'!$K17=""),'Cost Margin'!$B$9,'Cost Margin'!$K17),Z$6))))) -> 0 | AB9: =IF('Cost Margin'!A17="","",IF('Cost Margin'!E17="","(unassigned)",'Cost Margin'!E17))
A10: 2 | B10: =IF('Cost Margin'!A18="","",'Cost Margin'!A18&IF('Cost Margin'!E18="",""," · "&'Cost Margin'!E18)) | C10: =IF(OR(C$5="",'Cost Margin'!$A18="",IF(OR('Cost Margin'!$B$14="Y",'Cost Margin'!$J18=""),'Cost Margin'!$B$8,'Cost Margin'!$J18)="",IF(OR('Cost Margin'!$B$14="Y",'Cost Margin'!$K18=""),'Cost Margin'!$B$9,'Cost Margin'!$K18)=""),0,IF(MIN(IF(OR('Cost Margin'!$B$14="Y",'Cost Margin'!$K18=""),'Cost Margin'!$B$9,'Cost Margin'!$K18),C$6)<MAX(IF(OR('Cost Margin'!$B$14="Y",'Cost Margin'!$J18=""),'Cost Margin'!$B$8,'Cost Margin'!$J18),C$5),0,IFERROR(NETWORKDAYS(MAX(IF(OR('Cost Margin'!$B$14="Y",'Cost Margin'!$J18=""),'Cost Margin'!$B$8,'Cost Margin'!$J18),C$5),MIN(IF(OR('Cost Margin'!$B$14="Y",'Cost Margin'!$K18=""),'Cost Margin'!$B$9,'Cost Margin'!$K18),C$6),INDEX(Settings!$A$35:$D$74,0,MATCH('Cost Margin'!$C18,Settings!$A$34:$D$34,0))),NETWORKDAYS(MAX(IF(OR('Cost Margin'!$B$14="Y",'Cost Margin'!$J18=""),'Cost Margin'!$B$8,'Cost Margin'!$J18),C$5),MIN(IF(OR('Cost Margin'!$B$14="Y",'Cost Margin'!$K18=""),'Cost Margin'!$B$9,'Cost Margin'!$K18),C$6))))) -> 0 | D10: =IF(OR(D$5="",'Cost Margin'!$A18="",IF(OR('Cost Margin'!$B$14="Y",'Cost Margin'!$J18=""),'Cost Margin'!$B$8,'Cost Margin'!$J18)="",IF(OR('Cost Margin'!$B$14="Y",'Cost Margin'!$K18=""),'Cost Margin'!$B$9,'Cost Margin'!$K18)=""),0,IF(MIN(IF(OR('Cost Margin'!$B$14="Y",'Cost Margin'!$K18=""),'Cost Margin'!$B$9,'Cost Margin'!$K18),D$6)<MAX(IF(OR('Cost Margin'!$B$14="Y",'Cost Margin'!$J18=""),'Cost Margin'!$B$8,'Cost Margin'!$J18),D$5),0,IFERROR(NETWORKDAYS(MAX(IF(OR('Cost Margin'!$B$14="Y",'Cost Margin'!$J18=""),'Cost Margin'!$B$8,'Cost Margin'!$J18),D$5),MIN(IF(OR('Cost Margin'!$B$14="Y",'Cost Margin'!$K18=""),'Cost Margin'!$B$9,'Cost Margin'!$K18),D$6),INDEX(Settings!$A$35:$D$74,0,MATCH('Cost Margin'!$C18,Settings!$A$34:$D$34,0))),NETWORKDAYS(MAX(IF(OR('Cost Margin'!$B$14="Y",'Cost Margin'!$J18=""),'Cost Margin'!$B$8,'Cost Margin'!$J18),D$5),MIN(IF(OR('Cost Margin'!$B$14="Y",'Cost Margin'!$K18=""),'Cost Margin'!$B$9,'Cost Margin'!$K18),D$6))))) -> 0 | E10: =IF(OR(E$5="",'Cost Margin'!$A18="",IF(OR('Cost Margin'!$B$14="Y",'Cost Margin'!$J18=""),'Cost Margin'!$B$8,'Cost Margin'!$J18)="",IF(OR('Cost Margin'!$B$14="Y",'Cost Margin'!$K18=""),'Cost Margin'!$B$9,'Cost Margin'!$K18)=""),0,IF(MIN(IF(OR('Cost Margin'!$B$14="Y",'Cost Margin'!$K18=""),'Cost Margin'!$B$9,'Cost Margin'!$K18),E$6)<MAX(IF(OR('Cost Margin'!$B$14="Y",'Cost Margin'!$J18=""),'Cost Margin'!$B$8,'Cost Margin'!$J18),E$5),0,IFERROR(NETWORKDAYS(MAX(IF(OR('Cost Margin'!$B$14="Y",'Cost Margin'!$J18=""),'Cost Margin'!$B$8,'Cost Margin'!$J18),E$5),MIN(IF(OR('Cost Margin'!$B$14="Y",'Cost Margin'!$K18=""),'Cost Margin'!$B$9,'Cost Margin'!$K18),E$6),INDEX(Settings!$A$35:$D$74,0,MATCH('Cost Margin'!$C18,Settings!$A$34:$D$34,0))),NETWORKDAYS(MAX(IF(OR('Cost Margin'!$B$14="Y",'Cost Margin'!$J18=""),'Cost Margin'!$B$8,'Cost Margin'!$J18),E$5),MIN(IF(OR('Cost Margin'!$B$14="Y",'Cost Margin'!$K18=""),'Cost Margin'!$B$9,'Cost Margin'!$K18),E$6))))) -> 0 | F10: =IF(OR(F$5="",'Cost Margin'!$A18="",IF(OR('Cost Margin'!$B$14="Y",'Cost Margin'!$J18=""),'Cost Margin'!$B$8,'Cost Margin'!$J18)="",IF(OR('Cost Margin'!$B$14="Y",'Cost Margin'!$K18=""),'Cost Margin'!$B$9,'Cost Margin'!$K18)=""),0,IF(MIN(IF(OR('Cost Margin'!$B$14="Y",'Cost Margin'!$K18=""),'Cost Margin'!$B$9,'Cost Margin'!$K18),F$6)<MAX(IF(OR('Cost Margin'!$B$14="Y",'Cost Margin'!$J18=""),'Cost Margin'!$B$8,'Cost Margin'!$J18),F$5),0,IFERROR(NETWORKDAYS(MAX(IF(OR('Cost Margin'!$B$14="Y",'Cost Margin'!$J18=""),'Cost Margin'!$B$8,'Cost Margin'!$J18),F$5),MIN(IF(OR('Cost Margin'!$B$14="Y",'Cost Margin'!$K18=""),'Cost Margin'!$B$9,'Cost Margin'!$K18),F$6),INDEX(Settings!$A$35:$D$74,0,MATCH('Cost Margin'!$C18,Settings!$A$34:$D$34,0))),NETWORKDAYS(MAX(IF(OR('Cost Margin'!$B$14="Y",'Cost Margin'!$J18=""),'Cost Margin'!$B$8,'Cost Margin'!$J18),F$5),MIN(IF(OR('Cost Margin'!$B$14="Y",'Cost Margin'!$K18=""),'Cost Margin'!$B$9,'Cost Margin'!$K18),F$6))))) -> 0 | G10: =IF(OR(G$5="",'Cost Margin'!$A18="",IF(OR('Cost Margin'!$B$14="Y",'Cost Margin'!$J18=""),'Cost Margin'!$B$8,'Cost Margin'!$J18)="",IF(OR('Cost Margin'!$B$14="Y",'Cost Margin'!$K18=""),'Cost Margin'!$B$9,'Cost Margin'!$K18)=""),0,IF(MIN(IF(OR('Cost Margin'!$B$14="Y",'Cost Margin'!$K18=""),'Cost Margin'!$B$9,'Cost Margin'!$K18),G$6)<MAX(IF(OR('Cost Margin'!$B$14="Y",'Cost Margin'!$J18=""),'Cost Margin'!$B$8,'Cost Margin'!$J18),G$5),0,IFERROR(NETWORKDAYS(MAX(IF(OR('Cost Margin'!$B$14="Y",'Cost Margin'!$J18=""),'Cost Margin'!$B$8,'Cost Margin'!$J18),G$5),MIN(IF(OR('Cost Margin'!$B$14="Y",'Cost Margin'!$K18=""),'Cost Margin'!$B$9,'Cost Margin'!$K18),G$6),INDEX(Settings!$A$35:$D$74,0,MATCH('Cost Margin'!$C18,Settings!$A$34:$D$34,0))),NETWORKDAYS(MAX(IF(OR('Cost Margin'!$B$14="Y",'Cost Margin'!$J18=""),'Cost Margin'!$B$8,'Cost Margin'!$J18),G$5),MIN(IF(OR('Cost Margin'!$B$14="Y",'Cost Margin'!$K18=""),'Cost Margin'!$B$9,'Cost Margin'!$K18),G$6))))) -> 0 | H10: =IF(OR(H$5="",'Cost Margin'!$A18="",IF(OR('Cost Margin'!$B$14="Y",'Cost Margin'!$J18=""),'Cost Margin'!$B$8,'Cost Margin'!$J18)="",IF(OR('Cost Margin'!$B$14="Y",'Cost Margin'!$K18=""),'Cost Margin'!$B$9,'Cost Margin'!$K18)=""),0,IF(MIN(IF(OR('Cost Margin'!$B$14="Y",'Cost Margin'!$K18=""),'Cost Margin'!$B$9,'Cost Margin'!$K18),H$6)<MAX(IF(OR('Cost Margin'!$B$14="Y",'Cost Margin'!$J18=""),'Cost Margin'!$B$8,'Cost Margin'!$J18),H$5),0,IFERROR(NETWORKDAYS(MAX(IF(OR('Cost Margin'!$B$14="Y",'Cost Margin'!$J18=""),'Cost Margin'!$B$8,'Cost Margin'!$J18),H$5),MIN(IF(OR('Cost Margin'!$B$14="Y",'Cost Margin'!$K18=""),'Cost Margin'!$B$9,'Cost Margin'!$K18),H$6),INDEX(Settings!$A$35:$D$74,0,MATCH('Cost Margin'!$C18,Settings!$A$34:$D$34,0))),NETWORKDAYS(MAX(IF(OR('Cost Margin'!$B$14="Y",'Cost Margin'!$J18=""),'Cost Margin'!$B$8,'Cost Margin'!$J18),H$5),MIN(IF(OR('Cost Margin'!$B$14="Y",'Cost Margin'!$K18=""),'Cost Margin'!$B$9,'Cost Margin'!$K18),H$6))))) -> 0 | I10: =IF(OR(I$5="",'Cost Margin'!$A18="",IF(OR('Cost Margin'!$B$14="Y",'Cost Margin'!$J18=""),'Cost Margin'!$B$8,'Cost Margin'!$J18)="",IF(OR('Cost Margin'!$B$14="Y",'Cost Margin'!$K18=""),'Cost Margin'!$B$9,'Cost Margin'!$K18)=""),0,IF(MIN(IF(OR('Cost Margin'!$B$14="Y",'Cost Margin'!$K18=""),'Cost Margin'!$B$9,'Cost Margin'!$K18),I$6)<MAX(IF(OR('Cost Margin'!$B$14="Y",'Cost Margin'!$J18=""),'Cost Margin'!$B$8,'Cost Margin'!$J18),I$5),0,IFERROR(NETWORKDAYS(MAX(IF(OR('Cost Margin'!$B$14="Y",'Cost Margin'!$J18=""),'Cost Margin'!$B$8,'Cost Margin'!$J18),I$5),MIN(IF(OR('Cost Margin'!$B$14="Y",'Cost Margin'!$K18=""),'Cost Margin'!$B$9,'Cost Margin'!$K18),I$6),INDEX(Settings!$A$35:$D$74,0,MATCH('Cost Margin'!$C18,Settings!$A$34:$D$34,0))),NETWORKDAYS(MAX(IF(OR('Cost Margin'!$B$14="Y",'Cost Margin'!$J18=""),'Cost Margin'!$B$8,'Cost Margin'!$J18),I$5),MIN(IF(OR('Cost Margin'!$B$14="Y",'Cost Margin'!$K18=""),'Cost Margin'!$B$9,'Cost Margin'!$K18),I$6))))) -> 0 | J10: =IF(OR(J$5="",'Cost Margin'!$A18="",IF(OR('Cost Margin'!$B$14="Y",'Cost Margin'!$J18=""),'Cost Margin'!$B$8,'Cost Margin'!$J18)="",IF(OR('Cost Margin'!$B$14="Y",'Cost Margin'!$K18=""),'Cost Margin'!$B$9,'Cost Margin'!$K18)=""),0,IF(MIN(IF(OR('Cost Margin'!$B$14="Y",'Cost Margin'!$K18=""),'Cost Margin'!$B$9,'Cost Margin'!$K18),J$6)<MAX(IF(OR('Cost Margin'!$B$14="Y",'Cost Margin'!$J18=""),'Cost Margin'!$B$8,'Cost Margin'!$J18),J$5),0,IFERROR(NETWORKDAYS(MAX(IF(OR('Cost Margin'!$B$14="Y",'Cost Margin'!$J18=""),'Cost Margin'!$B$8,'Cost Margin'!$J18),J$5),MIN(IF(OR('Cost Margin'!$B$14="Y",'Cost Margin'!$K18=""),'Cost Margin'!$B$9,'Cost Margin'!$K18),J$6),INDEX(Settings!$A$35:$D$74,0,MATCH('Cost Margin'!$C18,Settings!$A$34:$D$34,0))),NETWORKDAYS(MAX(IF(OR('Cost Margin'!$B$14="Y",'Cost Margin'!$J18=""),'Cost Margin'!$B$8,'Cost Margin'!$J18),J$5),MIN(IF(OR('Cost Margin'!$B$14="Y",'Cost Margin'!$K18=""),'Cost Margin'!$B$9,'Cost Margin'!$K18),J$6))))) -> 0 | ... Z10: =IF(OR(Z$5="",'Cost Margin'!$A18="",IF(OR('Cost Margin'!$B$14="Y",'Cost Margin'!$J18=""),'Cost Margin'!$B$8,'Cost Margin'!$J18)="",IF(OR('Cost Margin'!$B$14="Y",'Cost Margin'!$K18=""),'Cost Margin'!$B$9,'Cost Margin'!$K18)=""),0,IF(MIN(IF(OR('Cost Margin'!$B$14="Y",'Cost Margin'!$K18=""),'Cost Margin'!$B$9,'Cost Margin'!$K18),Z$6)<MAX(IF(OR('Cost Margin'!$B$14="Y",'Cost Margin'!$J18=""),'Cost Margin'!$B$8,'Cost Margin'!$J18),Z$5),0,IFERROR(NETWORKDAYS(MAX(IF(OR('Cost Margin'!$B$14="Y",'Cost Margin'!$J18=""),'Cost Margin'!$B$8,'Cost Margin'!$J18),Z$5),MIN(IF(OR('Cost Margin'!$B$14="Y",'Cost Margin'!$K18=""),'Cost Margin'!$B$9,'Cost Margin'!$K18),Z$6),INDEX(Settings!$A$35:$D$74,0,MATCH('Cost Margin'!$C18,Settings!$A$34:$D$34,0))),NETWORKDAYS(MAX(IF(OR('Cost Margin'!$B$14="Y",'Cost Margin'!$J18=""),'Cost Margin'!$B$8,'Cost Margin'!$J18),Z$5),MIN(IF(OR('Cost Margin'!$B$14="Y",'Cost Margin'!$K18=""),'Cost Margin'!$B$9,'Cost Margin'!$K18),Z$6))))) -> 0 | AB10: =IF('Cost Margin'!A18="","",IF('Cost Margin'!E18="","(unassigned)",'Cost Margin'!E18))
